Workbook

Sheet Leggimi
A1: Prospetto esborsi Bachelor — Francesca, Marco, Iacopo (stima ponderata per probabilità)
A2: Aggiornato al 5 ottobre 2026. Valori in euro nominali (indicizzati). Solo bachelor: i master verranno trattati separatamente.
A4: COME LEGGERE IL FILE
A5: 1. 'Parametri': tassi di crescita, costo del mantenimento per città e rette per ateneo. Le celle in BLU su sfondo giallo sono gli input: cambiandole si ricalcola tutto.
A6: 2. 'Francesca', 'Marco', 'Iacopo': per ciascuno una CASCATA di opzioni in ordine di preferenza (riga 1 = dove andrebbe se ammesso ovunque). P(ammissione) è l'input; P(iscrizione) è calcolata: P(ammesso qui) × P(non ammesso in tutte le righe sopra). L'ultima riga è il ripiego a Milano (P=100%), così le probabilità di iscrizione sommano sempre a 100%.
A7: 3. Per ogni opzione: costo annuo nominale per anno accademico (retta indicizzata + mantenimento indicizzato + una tantum 1° anno) e costo atteso = P(iscrizione) × costo totale del percorso.
A8: 4. 'Cumulativo': esborso atteso per anno accademico dei tre ragazzi, cumulato, con tre scenari di confronto (più probabile, economico, caro).
A9: 5. 'Fonti': link alle pagine ufficiali usate per rette e costi (ottobre 2026).
A11: IPOTESI PRINCIPALI
A12: • Famiglia in fascia contributiva massima ovunque (nessuna borsa/ISEE); sussidi come la SU danese o le borse SUSI irlandesi esclusi.
A13: • Mantenimento fuori sede = 12 mesi, alloggio di buona qualità (studio o camera in studentato/privato), vitto e tempo libero senza economie estreme, 4-5 rientri a Milano l'anno, polizza integrativa, libri, arredo/depositi del 1° anno. Studente che vive a casa a Milano: solo spese aggiuntive (ATM, libri, pasti fuori, telefono).
A14: • Rette: base 2026/27 (o 2027/28 dove già pubblicata) indicizzata al 2,5%/anno (Forward College 5%, IE 2,9% come dichiarato). Mantenimento indicizzato al 3%/anno dal 2026.
... A21: • Esclusi: master, eventuale anno di studio all'estero con costi diversi (Sciences Po 3° anno, ESCP Londra), tasse di candidatura minori, auto/moto, spese sanitarie straordinarie, inflazione oltre i tassi ipotizzati.

Sheet Cumulativo
A1: ESBORSO CUMULATIVO — valore atteso ponderato per probabilità e scenari (bachelor)
A2: Euro nominali per anno accademico (settembre→agosto). Riga 'cumulato' = somma progressiva.
B3: 2027 | C3: 2028 | D3: 2029 | E3: 2030 | F3: 2031 | G3: 2032
A4: Anno accademico | B4: 2027/28 | C4: 2028/29 | D4: 2029/30 | E4: 2030/31 | F4: 2031/32 | G4: 2032/33 | H4: Totale percorso | I4: Nota
A5: A) VALORE ATTESO (ponderato per P(iscrizione))
A6: Francesca — atteso | B6: =Francesca!T15 -> 30865.987 | C6: =Francesca!U15 -> 31690.489 | D6: =Francesca!V15 -> 32615.243 | E6: =Francesca!W15 -> 8593.1564 | F6: =Francesca!X15 -> 0 | G6: =Francesca!Y15 -> 0 | H6: =SUM(B6:G6) -> 103764.87 | I6: Somma su tutte le opzioni della cascata
A7: Marco — atteso | B7: =Marco!T13 -> 0 | C7: =Marco!U13 -> 32669.936 | D7: =Marco!V13 -> 33607.824 | E7: =Marco!W13 -> 34572.794 | F7: =Marco!X13 -> 10174.406 | G7: =Marco!Y13 -> 0 | H7: =SUM(B7:G7) -> 111024.96
A8: Iacopo — atteso | B8: =Iacopo!T14 -> 0 | C8: =Iacopo!U14 -> 37958.295 | D8: =Iacopo!V14 -> 38363.854 | E8: =Iacopo!W14 -> 39501.629 | F8: =Iacopo!X14 -> 8105.6263 | G8: =Iacopo!Y14 -> 0 | H8: =SUM(B8:G8) -> 123929.4
A9: Totale famiglia | B9: =SUM(B6:B8) -> 30865.987 | C9: =SUM(C6:C8) -> 102318.72 | D9: =SUM(D6:D8) -> 104586.92 | E9: =SUM(E6:E8) -> 82667.579 | F9: =SUM(F6:F8) -> 18280.032 | G9: =SUM(G6:G8) -> 0 | H9: =SUM(B9:G9) -> 338719.24
A10: Cumulato progressivo | B10: =SUM($B$9:B9) -> 30865.987 | C10: =SUM($B$9:C9) -> 133184.71 | D10: =SUM($B$9:D9) -> 237771.63 | E10: =SUM($B$9:E9) -> 320439.21 | F10: =SUM($B$9:F9) -> 338719.24 | G10: =SUM($B$9:G9) -> 338719.24
A12: B) SCENARIO PIÙ PROBABILE (ciascuno nell'opzione con la P(iscrizione) più alta)
A13: Francesca | B13: =Francesca!N17 -> 29551 | C13: =Francesca!O17 -> 30423.675 | D13: =Francesca!P17 -> 31322.184 | E13: =Francesca!Q17 -> 11286.553 | F13: =Francesca!R17 -> 0 | G13: =Francesca!S17 -> 0 | H13: =SUM(B13:G13) -> 102583.41 | I13: =Francesca!C17 -> Rotterdam EUR — IBEB
A14: Marco | B14: =Marco!N15 -> 0 | C14: =Marco!O15 -> 30423.675 | D14: =Marco!P15 -> 31322.184 | E14: =Marco!Q15 -> 32247.293 | F14: =Marco!R15 -> 0 | G14: =Marco!S15 -> 0 | H14: =SUM(B14:G14) -> 93993.152 | I14: =Marco!C15 -> Rotterdam RSM — IBA
A15: Iacopo | B15: =Iacopo!N16 -> 0 | C15: =Iacopo!O16 -> 34667.275 | D15: =Iacopo!P16 -> 35693.092 | E15: =Iacopo!Q16 -> 36749.328 | F15: =Iacopo!R16 -> 0 | G15: =Iacopo!S16 -> 0 | H15: =SUM(B15:G15) -> 107109.7 | I15: =Iacopo!C16 -> UvA Amsterdam — Economics & Business Economics
A16: Totale famiglia | B16: =SUM(B13:B15) -> 29551 | C16: =SUM(C13:C15) -> 95514.625 | D16: =SUM(D13:D15) -> 98337.46 | E16: =SUM(E13:E15) -> 80283.174 | F16: =SUM(F13:F15) -> 0 | G16: =SUM(G13:G15) -> 0 | H16: =SUM(B16:G16) -> 303686.26
A17: Cumulato progressivo | B17: =SUM($B$16:B16) -> 29551 | C17: =SUM($B$16:C16) -> 125065.62 | D17: =SUM($B$16:D16) -> 223403.08 | E17: =SUM($B$16:E16) -> 303686.26 | F17: =SUM($B$16:F16) -> 303686.26 | G17: =SUM($B$16:G16) -> 303686.26
A19: C) SCENARIO ECONOMICO (opzione meno cara tra quelle con P(iscrizione) ≥ soglia)
A20: Francesca | B20: =Francesca!N18 -> 25220 | C20: =Francesca!O18 -> 25461.6 | D20: =Francesca!P18 -> 26225.448 | E20: =Francesca!Q18 -> 0 | F20: =Francesca!R18 -> 0 | G20: =Francesca!S18 -> 0 | H20: =SUM(B20:G20) -> 76907.048 | I20: =Francesca!C18 -> CBS Copenhagen — BSc (IB / BADM / BASM)
A21: Marco | B21: =Marco!N16 -> 0 | C21: =Marco!O16 -> 20831.145 | D21: =Marco!P16 -> 21366.776 | E21: =Marco!Q16 -> 21916.244 | F21: =Marco!R16 -> 0 | G21: =Marco!S16 -> 0 | H21: =SUM(B21:G21) -> 64114.165 | I21: =Marco!C16 -> Bocconi — CLEAM/Management/BIEM
A22: Iacopo | B22: =Iacopo!N17 -> 0 | C22: =Iacopo!O17 -> 34667.275 | D22: =Iacopo!P17 -> 35693.092 | E22: =Iacopo!Q17 -> 36749.328 | F22: =Iacopo!R17 -> 0 | G22: =Iacopo!S17 -> 0 | H22: =SUM(B22:G22) -> 107109.7 | I22: =Iacopo!C17 -> UvA Amsterdam — Economics & Business Economics
A23: Totale famiglia | B23: =SUM(B20:B22) -> 25220 | C23: =SUM(C20:C22) -> 80960.02 | D23: =SUM(D20:D22) -> 83285.316 | E23: =SUM(E20:E22) -> 58665.572 | F23: =SUM(F20:F22) -> 0 | G23: =SUM(G20:G22) -> 0 | H23: =SUM(B23:G23) -> 248130.91
A24: Cumulato progressivo | B24: =SUM($B$23:B23) -> 25220 | C24: =SUM($B$23:C23) -> 106180.02 | D24: =SUM($B$23:D23) -> 189465.34 | E24: =SUM($B$23:E23) -> 248130.91 | F24: =SUM($B$23:F23) -> 248130.91 | G24: =SUM($B$23:G23) -> 248130.91
A26: D) SCENARIO CARO (opzione più cara tra quelle con P(iscrizione) ≥ soglia)
A27: Francesca | B27: =Francesca!N19 -> 39992.5 | C27: =Francesca!O19 -> 41115.912 | D27: =Francesca!P19 -> 42271.118 | E27: =Francesca!Q19 -> 0 | F27: =Francesca!R19 -> 0 | G27: =Francesca!S19 -> 0 | H27: =SUM(B27:G27) -> 123379.53 | I27: =Francesca!C19 -> Sciences Po — Bachelor Collège universitaire
A28: Marco | B28: =Marco!N17 -> 0 | C28: =Marco!O17 -> 50476.8 | D28: =Marco!P17 -> 51881.942 | E28: =Marco!Q17 -> 53326.508 | F28: =Marco!R17 -> 54811.615 | G28: =Marco!S17 -> 0 | H28: =SUM(B28:G28) -> 210496.86 | I28: =Marco!C17 -> ESADE Barcellona — BBA / GGELO
A29: Iacopo | B29: =Iacopo!N18 -> 0 | C29: =Iacopo!O18 -> 64639.789 | D29: =Iacopo!P18 -> 60007.776 | E29: =Iacopo!Q18 -> 61776.413 | F29: =Iacopo!R18 -> 63597.192 | G29: =Iacopo!S18 -> 0 | H29: =SUM(B29:G29) -> 250021.17 | I29: =Iacopo!C18 -> IE University Madrid — BBA
A30: Totale famiglia | B30: =SUM(B27:B29) -> 39992.5 | C30: =SUM(C27:C29) -> 156232.5 | D30: =SUM(D27:D29) -> 154160.84 | E30: =SUM(E27:E29) -> 115102.92 | F30: =SUM(F27:F29) -> 118408.81 | G30: =SUM(G27:G29) -> 0 | H30: =SUM(B30:G30) -> 583897.56
A31: Cumulato progressivo | B31: =SUM($B$30:B30) -> 39992.5 | C31: =SUM($B$30:C30) -> 196225 | D31: =SUM($B$30:D30) -> 350385.84 | E31: =SUM($B$30:E30) -> 465488.76 | F31: =SUM($B$30:F30) -> 583897.56 | G31: =SUM($B$30:G30) -> 583897.56
A33: SINTESI TOTALE PERCORSO (3 bachelor)
A34: Valore atteso | H34: =H9 -> 338719.24
A35: Scenario più probabile | H35: =H16 -> 303686.26
A36: Scenario economico | H36: =H23 -> 248130.91
A37: Scenario caro | H37: =H30 -> 583897.56
A39: Nota: gli scenari B-D non sono ponderati; servono a leggere il range. Il valore atteso include anche i casi a bassa probabilità (es. Sciences Po, Dublino).

Sheet Parametri
A1: PARAMETRI GENERALI
A3: Parametro | B3: Valore | D3: Nota
A4: Crescita annua rette (default) | B4: 0.025 | D4: Storico Bocconi +1,8% 2025→26; Sciences Po +2-3%/anno; NL indicizzata inflazione
A5: Crescita annua mantenimento | B5: 0.03 | D5: Affitti studenteschi +3-7%/anno nelle grandi città NL/ES/IE
A6: Anno base mantenimento | B6: 2026 | D6: Le stime di costo della vita sono 2026
A7: Anno di ingresso Francesca | B7: 2027 | D7: a.a. 2027/28
A8: Anno di ingresso Marco e Iacopo | B8: 2028 | D8: a.a. 2028/29
A9: Quota BSc² (4 anni) se Rotterdam — Francesca | B9: 0.35 | D9: Se ammessa a Rotterdam: 35% che scelga il doppio bachelor Econometrics & Economics (4 anni) invece di IBEB (3)
A10: Soglia P(iscrizione) per scenari econ./caro | B10: 0.05 | D10: Negli scenari si considerano solo le opzioni con almeno questa probabilità di iscrizione
A12: MANTENIMENTO ANNUO PER CITTÀ (base 2026, 12 mesi, escluse rette)
A13: Città | B13: €/anno base 2026 | H13: Composizione / fonte
A14: Milano (a casa) | B14: 2800 | H14: Studente che vive in famiglia: ATM under 27 ~200, libri 400-700, pasti fuori 1.000-1.400, telefono, svago extra (Federconsumatori 2025)
A15: Rotterdam | B15: 26000 | H15: Studio/camera di qualità ~1.050/mese (Kamernet/kamer.nl 2025-26: camera 700-790, studio 1.250+), vitto e svago 750/mese, libri/assic./bici 2.000, voli 900, extra 1.500 (EUR: 1.000-1.800/mese)
A16: Amsterdam | B16: 30000 | H16: Studio ~1.400/mese (kamer.nl 1.408; camera 850-990), vitto e svago 800/mese, 2.000 libri/assic./bici, voli 900, extra 1.500 (AUAS: 1.200-1.800/mese)
A17: Tilburg | B17: 23000 | H17: Studio ~850/mese (camera 535-592), vitto 700/mese, 2.000, voli 900, extra 1.500 (Tilburg: 1.000-1.200/mese)
A18: Maastricht | B18: 23500 | H18: Studio ~900/mese (camera 565-625), vitto 700/mese, 2.000, voli 900, extra 1.500
A19: Delft | B19: 22500 | H19: Camera/studio studentato ~800/mese, vitto 700, 2.000, voli 900, extra 1.500 (TU Delft: ~909/mese medio)
A20: Parigi | B20: 24000 | H20: Studio 1.000-1.100/mese (LocService 2025-26: studio 917-962), vitto/trasporti/svago 900-1.000/mese, voli 700-900 (UNEF: budget 1.627/mese)
A21: Reims | B21: 16000 | H21: Studio 500-600/mese (LocService 2026: T1 461), resto 750-850/mese — campus Sciences Po / PEM anni 1-2
A22: ESCP (media 3 campus) | B22: 23000 | H22: Media di Parigi 24.000, Londra ~29.000 (£25k), Torino/Madrid/Berlino ~16-20.000 — un anno per campus
A23: Forward College (Lisbona/Parigi/Berlino) | B23: 21700 | H23: Media dei tre anni: Lisbona ~20.000, Parigi ~24.000, Berlino ~21.000 (stime Forward: alloggio 7.150-15.600/anno + vitto)
A24: Madrid | B24: 26000 | H24: Tra scenario camera (750/mese, 24.000) e studio (1.100/mese, 28.000); Idealista Q2-Q3 2026 camera 550, studio 976; IE: camera 600-1.100, studio 800-1.600
A25: Barcellona | B25: 27000 | H25: Tra camera (800/mese, 25.000) e studio (1.150/mese, 29.000); Idealista 2026 camera 600, studio 960
... A27: Dublino | B27: 30000 | H27: Alloggio 1.200/mese (mediana UCD; Daft Q1 2026 camera 874-1.007, monolocale 1.966), vitto/utenze/svago 1.275/mese, voli 1.000 (UCD stima 2.445/mese)
A29: RETTE PER ATENEO/CORSO (fascia massima, studente UE)
A30: Opzione (chiave) | B30: Retta annua base € | C30: Anno base retta | D30: Anni | E30: Crescita retta | F30: Una tantum 1° anno € | G30: Città | H30: Note / fonte
A31: Bocconi — CLEAM/Management/BIEM | B31: 17000 | C31: 2026 | D31: 3 | E31: =Parametri!$B$4 -> 0.025 | F31: 0 | G31: Milano (a casa) | H31: 2026/27: 17.000 tutto compreso (tassa regionale e bolli inclusi), uguale per tutti i bachelor; 2025/26 era 16.700
A32: Cattolica Milano — Economia | B32: 11500 | C32: 2026 | D32: 3 | E32: =Parametri!$B$4 -> 0.025 | F32: 0 | G32: Milano (a casa) | H32: Fascia massima 2026/27 ricostruita dalla normativa: ~11.440-11.790 (Economia / Economics and Management). Usata come ripiego milanese
A33: Statale Milano — Economia/Scienze politiche | B33: 3410 | C33: 2026 | D33: 3 | E33: =Parametri!$B$4 -> 0.025 | F33: 0 | G33: Milano (a casa) | H33: ISEE >80.000: 3.204 + tassa regionale 190 + bollo 16 (2026/27). Per riferimento
A34: Rotterdam EUR — IBEB | B34: 2771 | C34: 2027 | D34: 3 | E34: =Parametri!$B$4 -> 0.025 | F34: 0 | G34: Rotterdam | H34: Retta statutaria NL 2027/28 già fissata: 2.771 (2026/27: 2.694). Numerus fixus 700 posti
A35: Rotterdam EUR — BSc² Econometrics & Economics | B35: 2771 | C35: 2027 | D35: 4 | E35: =Parametri!$B$4 -> 0.025 | F35: 0 | G35: Rotterdam | H35: 4 anni (264 ECTS), retta statutaria anche il 4° anno (da confermare con ESSC)
A36: Rotterdam RSM — IBA | B36: 2771 | C36: 2027 | D36: 3 | E36: =Parametri!$B$4 -> 0.025 | F36: 0 | G36: Rotterdam | H36: Numerus fixus 650 posti; 75% media + 25% motivazione; study trips 300-500/anno inclusi nel mantenimento
A37: UvA Amsterdam — Economics & Business Economics | B37: 2771 | C37: 2027 | D37: 3 | E37: =Parametri!$B$4 -> 0.025 | F37: 0 | G37: Amsterdam | H37: Numerus fixus 550 posti, selezione solo con test online (2026: offerte fino al 1.487° su ~1.500)
A38: VU Amsterdam — Economics & Business Economics | B38: 2771 | C38: 2027 | D38: 3 | E38: =Parametri!$B$4 -> 0.025 | F38: 0 | G38: Amsterdam | H38: Solo requisiti (matematica livello A / OMPT-A)
A39: Tilburg — Economics / IBA | B39: 2771 | C39: 2027 | D39: 3 | E39: =Parametri!$B$4 -> 0.025 | F39: 0 | G39: Tilburg | H39: Solo requisiti + matching; housing garantito 1° anno
A40: Maastricht SBE — International Business | B40: 2771 | C40: 2027 | D40: 3 | E40: =Parametri!$B$4 -> 0.025 | F40: 0 | G40: Maastricht | H40: Numerus fixus con selezione: essay 1/3, CV 1/3, voti penultimo anno 1/3
A41: Maastricht SBE — Economics & Business Economics | B41: 2771 | C41: 2027 | D41: 3 | E41: =Parametri!$B$4 -> 0.025 | F41: 0 | G41: Maastricht | H41: Solo requisiti + matching
A42: TU Delft — Computer Science & Engineering | B42: 2771 | C42: 2027 | D42: 3 | E42: =Parametri!$B$4 -> 0.025 | F42: 1350 | G42: Delft | H42: Per riferimento (Iacopo): numerus fixus con test mate/fisica; laptop obbligatorio ~1.350
... A44: ESCP — Bachelor in Management | B44: 20800 | C44: 2027 | D44: 3 | E44: =Parametri!$B$4 -> 0.025 | F44: 80 | G44: ESCP (media 3 campus) | H44: Intake 2027: 17.900 + 2.900 fees = 20.800, uguale per tutti i campus; application fee 80
A45: Forward College — Business & Management | B45: 21850 | C45: 2027 | D45: 3 | E45: 0.05 | F45: 70 | G45: Forward College (Lisbona/Parigi/Berlino) | H45: 2027/28 UE: 21.850, +5%/anno dichiarato; early bird -10% sul 1° anno entro 31/12/2026 non considerato; UoL enrolment ~70
...

Sheet Francesca
A1: FRANCESCA — cascata di opzioni, probabilità e costi
A2: Profilo: liceo scientifico bilingue quadriennale, media 8,4-8,5, inglese C1, test Bocconi settembre 2026 andato male (da ripetere). Preferisce l'estero; Bocconi non è la prima scelta ma resta davanti alle opzioni più care/meno prestigiose.
A3: Anno di ingresso (a.a. che inizia a settembre): | F3: =Parametri!$B$7 -> 2027 | G3: ← da Parametri | N3: Costo annuo nominale dell'opzione (non ponderato) | T3: Esborso atteso = P(iscrizione) × costo
N4: 2027 | O4: 2028 | P4: 2029 | Q4: 2030 | R4: 2031 | S4: 2032 | T4: 2027 | U4: 2028 | V4: 2029 | W4: 2030 | X4: 2031 | Y4: 2032
A5: # | B5: Opzione (chiave in Parametri) | C5: Città | D5: Anni | E5: P(ammiss.) | F5: P(iscriz.) | G5: Retta base € | H5: Anno base | I5: Mantenim. base € | J5: Una tantum € | K5: Costo 1° anno € | L5: Costo totale percorso € | M5: Costo atteso € | N5: Costo 2027/28 | O5: Costo 2028/29 | P5: Costo 2029/30 | Q5: Costo 2030/31 | R5: Costo 2031/32 | S5: Costo 2032/33 | T5: Atteso 2027/28 | U5: Atteso 2028/29 | V5: Atteso 2029/30 | W5: Atteso 2030/31 | X5: Atteso 2031/32 | Y5: Atteso 2032/33 | Z5: Motivazione della probabilità
A6: 1 | B6: Sciences Po — Bachelor Collège universitaire | C6: =INDEX(Parametri!$G$31:$G$52,MATCH($B6,Parametri!$A$31:$A$52,0)) -> Parigi | D6: =INDEX(Parametri!$D$31:$D$52,MATCH($B6,Parametri!$A$31:$A$52,0)) -> 3 | E6: 0.15 | F6: =E6 -> 0.15 | G6: =INDEX(Parametri!$B$31:$B$52,MATCH($B6,Parametri!$A$31:$A$52,0)) -> 14900 | H6: =INDEX(Parametri!$C$31:$C$52,MATCH($B6,Parametri!$A$31:$A$52,0)) -> 2026 | I6: =INDEX(Parametri!$B$14:$B$27,MATCH($C6,Parametri!$A$14:$A$27,0)) -> 24000 | J6: =INDEX(Parametri!$F$31:$F$52,MATCH($B6,Parametri!$A$31:$A$52,0)) -> 0 | K6: =INDEX(N6:S6,MATCH($F$3,$N$4:$S$4,0)) -> 39992.5 | L6: =SUM(N6:S6) -> 123379.53 | M6: =F6*L6 -> 18506.93 | N6: =IF(N$4<$F$3,0,MAX(0,MIN(1,$D6-(N$4-$F$3+1)+1))*($G6*(1+INDEX(Parametri!$E$31:$E$52,MATCH($B6,Parametri!$A$31:$A$52,0)))^(N$4-$H6)+$I6*(1+Parametri!$B$5)^(N$4-Parametri!$B$6)+IF(N$4=$F$3,$J6,0))) -> 39992.5 | O6: =IF(O$4<$F$3,0,MAX(0,MIN(1,$D6-(O$4-$F$3+1)+1))*($G6*(1+INDEX(Parametri!$E$31:$E$52,MATCH($B6,Parametri!$A$31:$A$52,0)))^(O$4-$H6)+$I6*(1+Parametri!$B$5)^(O$4-Parametri!$B$6)+IF(O$4=$F$3,$J6,0))) -> 41115.912 | P6: =IF(P$4<$F$3,0,MAX(0,MIN(1,$D6-(P$4-$F$3+1)+1))*($G6*(1+INDEX(Parametri!$E$31:$E$52,MATCH($B6,Parametri!$A$31:$A$52,0)))^(P$4-$H6)+$I6*(1+Parametri!$B$5)^(P$4-Parametri!$B$6)+IF(P$4=$F$3,$J6,0))) -> 42271.118 | Q6: =IF(Q$4<$F$3,0,MAX(0,MIN(1,$D6-(Q$4-$F$3+1)+1))*($G6*(1+INDEX(Parametri!$E$31:$E$52,MATCH($B6,Parametri!$A$31:$A$52,0)))^(Q$4-$H6)+$I6*(1+Parametri!$B$5)^(Q$4-Parametri!$B$6)+IF(Q$4=$F$3,$J6,0))) -> 0 | R6: =IF(R$4<$F$3,0,MAX(0,MIN(1,$D6-(R$4-$F$3+1)+1))*($G6*(1+INDEX(Parametri!$E$31:$E$52,MATCH($B6,Parametri!$A$31:$A$52,0)))^(R$4-$H6)+$I6*(1+Parametri!$B$5)^(R$4-Parametri!$B$6)+IF(R$4=$F$3,$J6,0))) -> 0 | S6: =IF(S$4<$F$3,0,MAX(0,MIN(1,$D6-(S$4-$F$3+1)+1))*($G6*(1+INDEX(Parametri!$E$31:$E$52,MATCH($B6,Parametri!$A$31:$A$52,0)))^(S$4-$H6)+$I6*(1+Parametri!$B$5)^(S$4-Parametri!$B$6)+IF(S$4=$F$3,$J6,0))) -> 0 | T6: =$F6*N6 -> 5998.875 | U6: =$F6*O6 -> 6167.3869 | V6: =$F6*P6 -> 6340.6677 | W6: =$F6*Q6 -> 0 | X6: =$F6*R6 -> 0 | Y6: =$F6*S6 -> 0 | Z6: Parcoursup 2025: ~10% ammessi, 92% con media >16/20; procedura internazionale <200 posti. Media 8,5 è sotto la mediana; C1 e dossier aiutano.
A7: 2 | B7: Rotterdam EUR — IBEB | C7: =INDEX(Parametri!$G$31:$G$52,MATCH($B7,Parametri!$A$31:$A$52,0)) -> Rotterdam | D7: =INDEX(Parametri!$D$31:$D$52,MATCH($B7,Parametri!$A$31:$A$52,0))+Parametri!$B$9 -> 3.35 | E7: 0.85 | F7: =E7*EXP(SUMPRODUCT(LN(1-$E$6:E6+($E$6:E6=1)*0.000000000001))) -> 0.7225 | G7: =INDEX(Parametri!$B$31:$B$52,MATCH($B7,Parametri!$A$31:$A$52,0)) -> 2771 | H7: =INDEX(Parametri!$C$31:$C$52,MATCH($B7,Parametri!$A$31:$A$52,0)) -> 2027 | I7: =INDEX(Parametri!$B$14:$B$27,MATCH($C7,Parametri!$A$14:$A$27,0)) -> 26000 | J7: =INDEX(Parametri!$F$31:$F$52,MATCH($B7,Parametri!$A$31:$A$52,0)) -> 0 | K7: =INDEX(N7:S7,MATCH($F$3,$N$4:$S$4,0)) -> 29551 | L7: =SUM(N7:S7) -> 102583.41 | M7: =F7*L7 -> 74116.515 | N7: =IF(N$4<$F$3,0,MAX(0,MIN(1,$D7-(N$4-$F$3+1)+1))*($G7*(1+INDEX(Parametri!$E$31:$E$52,MATCH($B7,Parametri!$A$31:$A$52,0)))^(N$4-$H7)+$I7*(1+Parametri!$B$5)^(N$4-Parametri!$B$6)+IF(N$4=$F$3,$J7,0))) -> 29551 | O7: =IF(O$4<$F$3,0,MAX(0,MIN(1,$D7-(O$4-$F$3+1)+1))*($G7*(1+INDEX(Parametri!$E$31:$E$52,MATCH($B7,Parametri!$A$31:$A$52,0)))^(O$4-$H7)+$I7*(1+Parametri!$B$5)^(O$4-Parametri!$B$6)+IF(O$4=$F$3,$J7,0))) -> 30423.675 | P7: =IF(P$4<$F$3,0,MAX(0,MIN(1,$D7-(P$4-$F$3+1)+1))*($G7*(1+INDEX(Parametri!$E$31:$E$52,MATCH($B7,Parametri!$A$31:$A$52,0)))^(P$4-$H7)+$I7*(1+Parametri!$B$5)^(P$4-Parametri!$B$6)+IF(P$4=$F$3,$J7,0))) -> 31322.184 | Q7: =IF(Q$4<$F$3,0,MAX(0,MIN(1,$D7-(Q$4-$F$3+1)+1))*($G7*(1+INDEX(Parametri!$E$31:$E$52,MATCH($B7,Parametri!$A$31:$A$52,0)))^(Q$4-$H7)+$I7*(1+Parametri!$B$5)^(Q$4-Parametri!$B$6)+IF(Q$4=$F$3,$J7,0))) -> 11286.553 | R7: =IF(R$4<$F$3,0,MAX(0,MIN(1,$D7-(R$4-$F$3+1)+1))*($G7*(1+INDEX(Parametri!$E$31:$E$52,MATCH($B7,Parametri!$A$31:$A$52,0)))^(R$4-$H7)+$I7*(1+Parametri!$B$5)^(R$4-Parametri!$B$6)+IF(R$4=$F$3,$J7,0))) -> 0 | S7: =IF(S$4<$F$3,0,MAX(0,MIN(1,$D7-(S$4-$F$3+1)+1))*($G7*(1+INDEX(Parametri!$E$31:$E$52,MATCH($B7,Parametri!$A$31:$A$52,0)))^(S$4-$H7)+$I7*(1+Parametri!$B$5)^(S$4-Parametri!$B$6)+IF(S$4=$F$3,$J7,0))) -> 0 | T7: =$F7*N7 -> 21350.597 | U7: =$F7*O7 -> 21981.105 | V7: =$F7*P7 -> 22630.278 | W7: =$F7*Q7 -> 8154.5342 | X7: =$F7*R7 -> 0 | Y7: =$F7*S7 -> 0 | Z7: Numerus fixus 700 posti: i primi 350 per pura media (mate ≥7 e inglese ok). Con 8,5 è nella fascia alta; rischio residuo diploma quadriennale e sorteggio.
A8: 3 | B8: CBS Copenhagen — BSc (IB / BADM / BASM) | C8: =INDEX(Parametri!$G$31:$G$52,MATCH($B8,Parametri!$A$31:$A$52,0)) -> Copenhagen | D8: =INDEX(Parametri!$D$31:$D$52,MATCH($B8,Parametri!$A$31:$A$52,0)) -> 3 | E8: 0.45 | F8: =E8*EXP(SUMPRODUCT(LN(1-$E$6:E7+($E$6:E7=1)*0.000000000001))) -> 0.057375 | G8: =INDEX(Parametri!$B$31:$B$52,MATCH($B8,Parametri!$A$31:$A$52,0)) -> 0 | H8: =INDEX(Parametri!$C$31:$C$52,MATCH($B8,Parametri!$A$31:$A$52,0)) -> 2026 | I8: =INDEX(Parametri!$B$14:$B$27,MATCH($C8,Parametri!$A$14:$A$27,0)) -> 24000 | J8: =INDEX(Parametri!$F$31:$F$52,MATCH($B8,Parametri!$A$31:$A$52,0)) -> 500 | K8: =INDEX(N8:S8,MATCH($F$3,$N$4:$S$4,0)) -> 25220 | L8: =SUM(N8:S8) -> 76907.048 | M8: =F8*L8 -> 4412.5419 | N8: =IF(N$4<$F$3,0,MAX(0,MIN(1,$D8-(N$4-$F$3+1)+1))*($G8*(1+INDEX(Parametri!$E$31:$E$52,MATCH($B8,Parametri!$A$31:$A$52,0)))^(N$4-$H8)+$I8*(1+Parametri!$B$5)^(N$4-Parametri!$B$6)+IF(N$4=$F$3,$J8,0))) -> 25220 | O8: =IF(O$4<$F$3,0,MAX(0,MIN(1,$D8-(O$4-$F$3+1)+1))*($G8*(1+INDEX(Parametri!$E$31:$E$52,MATCH($B8,Parametri!$A$31:$A$52,0)))^(O$4-$H8)+$I8*(1+Parametri!$B$5)^(O$4-Parametri!$B$6)+IF(O$4=$F$3,$J8,0))) -> 25461.6 | P8: =IF(P$4<$F$3,0,MAX(0,MIN(1,$D8-(P$4-$F$3+1)+1))*($G8*(1+INDEX(Parametri!$E$31:$E$52,MATCH($B8,Parametri!$A$31:$A$52,0)))^(P$4-$H8)+$I8*(1+Parametri!$B$5)^(P$4-Parametri!$B$6)+IF(P$4=$F$3,$J8,0))) -> 26225.448 | Q8: =IF(Q$4<$F$3,0,MAX(0,MIN(1,$D8-(Q$4-$F$3+1)+1))*($G8*(1+INDEX(Parametri!$E$31:$E$52,MATCH($B8,Parametri!$A$31:$A$52,0)))^(Q$4-$H8)+$I8*(1+Parametri!$B$5)^(Q$4-Parametri!$B$6)+IF(Q$4=$F$3,$J8,0))) -> 0 | R8: =IF(R$4<$F$3,0,MAX(0,MIN(1,$D8-(R$4-$F$3+1)+1))*($G8*(1+INDEX(Parametri!$E$31:$E$52,MATCH($B8,Parametri!$A$31:$A$52,0)))^(R$4-$H8)+$I8*(1+Parametri!$B$5)^(R$4-Parametri!$B$6)+IF(R$4=$F$3,$J8,0))) -> 0 | S8: =IF(S$4<$F$3,0,MAX(0,MIN(1,$D8-(S$4-$F$3+1)+1))*($G8*(1+INDEX(Parametri!$E$31:$E$52,MATCH($B8,Parametri!$A$31:$A$52,0)))^(S$4-$H8)+$I8*(1+Parametri!$B$5)^(S$4-Parametri!$B$6)+IF(S$4=$F$3,$J8,0))) -> 0 | T8: =$F8*N8 -> 1446.9975 | U8: =$F8*O8 -> 1460.8593 | V8: =$F8*P8 -> 1504.6851 | W8: =$F8*Q8 -> 0 | X8: =$F8*R8 -> 0 | Y8: =$F8*S8 -> 0 | Z8: Kvote 1: IB richiede 11,1/12 (quasi solo 95-100 di maturità); BADM/BASM 9,4-9,8 raggiungibili con 8,5 (~9-10 danese). Kvote 2 possibile.
A9: 4 | B9: Bocconi — CLEAM/Management/BIEM | C9: =INDEX(Parametri!$G$31:$G$52,MATCH($B9,Parametri!$A$31:$A$52,0)) -> Milano (a casa) | D9: =INDEX(Parametri!$D$31:$D$52,MATCH($B9,Parametri!$A$31:$A$52,0)) -> 3 | E9: 0.55 | F9: =E9*EXP(SUMPRODUCT(LN(1-$E$6:E8+($E$6:E8=1)*0.000000000001))) -> 0.03856875 | G9: =INDEX(Parametri!$B$31:$B$52,MATCH($B9,Parametri!$A$31:$A$52,0)) -> 17000 | H9: =INDEX(Parametri!$C$31:$C$52,MATCH($B9,Parametri!$A$31:$A$52,0)) -> 2026 | I9: =INDEX(Parametri!$B$14:$B$27,MATCH($C9,Parametri!$A$14:$A$27,0)) -> 2800 | J9: =INDEX(Parametri!$F$31:$F$52,MATCH($B9,Parametri!$A$31:$A$52,0)) -> 0 | K9: =INDEX(N9:S9,MATCH($F$3,$N$4:$S$4,0)) -> 20309 | L9: =SUM(N9:S9) -> 62506.921 | M9: =F9*L9 -> 2410.8138 | N9: =IF(N$4<$F$3,0,MAX(0,MIN(1,$D9-(N$4-$F$3+1)+1))*($G9*(1+INDEX(Parametri!$E$31:$E$52,MATCH($B9,Parametri!$A$31:$A$52,0)))^(N$4-$H9)+$I9*(1+Parametri!$B$5)^(N$4-Parametri!$B$6)+IF(N$4=$F$3,$J9,0))) -> 20309 | O9: =IF(O$4<$F$3,0,MAX(0,MIN(1,$D9-(O$4-$F$3+1)+1))*($G9*(1+INDEX(Parametri!$E$31:$E$52,MATCH($B9,Parametri!$A$31:$A$52,0)))^(O$4-$H9)+$I9*(1+Parametri!$B$5)^(O$4-Parametri!$B$6)+IF(O$4=$F$3,$J9,0))) -> 20831.145 | P9: =IF(P$4<$F$3,0,MAX(0,MIN(1,$D9-(P$4-$F$3+1)+1))*($G9*(1+INDEX(Parametri!$E$31:$E$52,MATCH($B9,Parametri!$A$31:$A$52,0)))^(P$4-$H9)+$I9*(1+Parametri!$B$5)^(P$4-Parametri!$B$6)+IF(P$4=$F$3,$J9,0))) -> 21366.776 | Q9: =IF(Q$4<$F$3,0,MAX(0,MIN(1,$D9-(Q$4-$F$3+1)+1))*($G9*(1+INDEX(Parametri!$E$31:$E$52,MATCH($B9,Parametri!$A$31:$A$52,0)))^(Q$4-$H9)+$I9*(1+Parametri!$B$5)^(Q$4-Parametri!$B$6)+IF(Q$4=$F$3,$J9,0))) -> 0 | R9: =IF(R$4<$F$3,0,MAX(0,MIN(1,$D9-(R$4-$F$3+1)+1))*($G9*(1+INDEX(Parametri!$E$31:$E$52,MATCH($B9,Parametri!$A$31:$A$52,0)))^(R$4-$H9)+$I9*(1+Parametri!$B$5)^(R$4-Parametri!$B$6)+IF(R$4=$F$3,$J9,0))) -> 0 | S9: =IF(S$4<$F$3,0,MAX(0,MIN(1,$D9-(S$4-$F$3+1)+1))*($G9*(1+INDEX(Parametri!$E$31:$E$52,MATCH($B9,Parametri!$A$31:$A$52,0)))^(S$4-$H9)+$I9*(1+Parametri!$B$5)^(S$4-Parametri!$B$6)+IF(S$4=$F$3,$J9,0))) -> 0 | T9: =$F9*N9 -> 783.29274 | U9: =$F9*O9 -> 803.43122 | V9: =$F9*P9 -> 824.08985 | W9: =$F9*Q9 -> 0 | X9: =$F9*R9 -> 0 | Y9: =$F9*S9 -> 0 | Z9: Formula 55% test / 45% media 3ª-4ª: media 8,4-8,5 sopra la mediana stimata; serve rifare il test a 30+/50 in Early 2026 per il 2027. Corsi in italiano meno selettivi.
A10: 5 | B10: UCD Dublino — Commerce / Economics | C10: =INDEX(Parametri!$G$31:$G$52,MATCH($B10,Parametri!$A$31:$A$52,0)) -> Dublino | D10: =INDEX(Parametri!$D$31:$D$52,MATCH($B10,Parametri!$A$31:$A$52,0)) -> 3 | E10: 0.7 | F10: =E10*EXP(SUMPRODUCT(LN(1-$E$6:E9+($E$6:E9=1)*0.000000000001))) -> 0.022089375 | G10: =INDEX(Parametri!$B$31:$B$52,MATCH($B10,Parametri!$A$31:$A$52,0)) -> 2754 | H10: =INDEX(Parametri!$C$31:$C$52,MATCH($B10,Parametri!$A$31:$A$52,0)) -> 2026 | I10: =INDEX(Parametri!$B$14:$B$27,MATCH($C10,Parametri!$A$14:$A$27,0)) -> 30000 | J10: =INDEX(Parametri!$F$31:$F$52,MATCH($B10,Parametri!$A$31:$A$52,0)) -> 0 | K10: =INDEX(N10:S10,MATCH($F$3,$N$4:$S$4,0)) -> 33722.85 | L10: =SUM(N10:S10) -> 104190.84 | M10: =F10*L10 -> 2301.5105 | N10: =IF(N$4<$F$3,0,MAX(0,MIN(1,$D10-(N$4-$F$3+1)+1))*($G10*(1+INDEX(Parametri!$E$31:$E$52,MATCH($B10,Parametri!$A$31:$A$52,0)))^(N$4-$H10)+$I10*(1+Parametri!$B$5)^(N$4-Parametri!$B$6)+IF(N$4=$F$3,$J10,0))) -> 33722.85 | O10: =IF(O$4<$F$3,0,MAX(0,MIN(1,$D10-(O$4-$F$3+1)+1))*($G10*(1+INDEX(Parametri!$E$31:$E$52,MATCH($B10,Parametri!$A$31:$A$52,0)))^(O$4-$H10)+$I10*(1+Parametri!$B$5)^(O$4-Parametri!$B$6)+IF(O$4=$F$3,$J10,0))) -> 34720.421 | P10: =IF(P$4<$F$3,0,MAX(0,MIN(1,$D10-(P$4-$F$3+1)+1))*($G10*(1+INDEX(Parametri!$E$31:$E$52,MATCH($B10,Parametri!$A$31:$A$52,0)))^(P$4-$H10)+$I10*(1+Parametri!$B$5)^(P$4-Parametri!$B$6)+IF(P$4=$F$3,$J10,0))) -> 35747.567 | Q10: =IF(Q$4<$F$3,0,MAX(0,MIN(1,$D10-(Q$4-$F$3+1)+1))*($G10*(1+INDEX(Parametri!$E$31:$E$52,MATCH($B10,Parametri!$A$31:$A$52,0)))^(Q$4-$H10)+$I10*(1+Parametri!$B$5)^(Q$4-Parametri!$B$6)+IF(Q$4=$F$3,$J10,0))) -> 0 | R10: =IF(R$4<$F$3,0,MAX(0,MIN(1,$D10-(R$4-$F$3+1)+1))*($G10*(1+INDEX(Parametri!$E$31:$E$52,MATCH($B10,Parametri!$A$31:$A$52,0)))^(R$4-$H10)+$I10*(1+Parametri!$B$5)^(R$4-Parametri!$B$6)+IF(R$4=$F$3,$J10,0))) -> 0 | S10: =IF(S$4<$F$3,0,MAX(0,MIN(1,$D10-(S$4-$F$3+1)+1))*($G10*(1+INDEX(Parametri!$E$31:$E$52,MATCH($B10,Parametri!$A$31:$A$52,0)))^(S$4-$H10)+$I10*(1+Parametri!$B$5)^(S$4-Parametri!$B$6)+IF(S$4=$F$3,$J10,0))) -> 0 | T10: =$F10*N10 -> 744.91668 | U10: =$F10*O10 -> 766.95241 | V10: =$F10*P10 -> 789.64141 | W10: =$F10*Q10 -> 0 | X10: =$F10*R10 -> 0 | Y10: =$F10*S10 -> 0 | Z10: Punti CAO 2025-26: Commerce 553-554, Economics 542-544 ≈ maturità 87-88 con la tabella CAO (90→574, 80→506). Diploma quadriennale da far riconoscere.
A11: 6 | B11: IE University Madrid — BBA | C11: =INDEX(Parametri!$G$31:$G$52,MATCH($B11,Parametri!$A$31:$A$52,0)) -> Madrid | D11: =INDEX(Parametri!$D$31:$D$52,MATCH($B11,Parametri!$A$31:$A$52,0)) -> 4 | E11: 0.75 | F11: =E11*EXP(SUMPRODUCT(LN(1-$E$6:E10+($E$6:E10=1)*0.000000000001))) -> 0.0071001562 | G11: =INDEX(Parametri!$B$31:$B$52,MATCH($B11,Parametri!$A$31:$A$52,0)) -> 29000 | H11: =INDEX(Parametri!$C$31:$C$52,MATCH($B11,Parametri!$A$31:$A$52,0)) -> 2026 | I11: =INDEX(Parametri!$B$14:$B$27,MATCH($C11,Parametri!$A$14:$A$27,0)) -> 26000 | J11: =INDEX(Parametri!$F$31:$F$52,MATCH($B11,Parametri!$A$31:$A$52,0)) -> 6350 | K11: =INDEX(N11:S11,MATCH($F$3,$N$4:$S$4,0)) -> 62971 | L11: =SUM(N11:S11) -> 243044.98 | M11: =F11*L11 -> 1725.6573 | N11: =IF(N$4<$F$3,0,MAX(0,MIN(1,$D11-(N$4-$F$3+1)+1))*($G11*(1+INDEX(Parametri!$E$31:$E$52,MATCH($B11,Parametri!$A$31:$A$52,0)))^(N$4-$H11)+$I11*(1+Parametri!$B$5)^(N$4-Parametri!$B$6)+IF(N$4=$F$3,$J11,0))) -> 62971 | O11: =IF(O$4<$F$3,0,MAX(0,MIN(1,$D11-(O$4-$F$3+1)+1))*($G11*(1+INDEX(Parametri!$E$31:$E$52,MATCH($B11,Parametri!$A$31:$A$52,0)))^(O$4-$H11)+$I11*(1+Parametri!$B$5)^(O$4-Parametri!$B$6)+IF(O$4=$F$3,$J11,0))) -> 58289.789 | P11: =IF(P$4<$F$3,0,MAX(0,MIN(1,$D11-(P$4-$F$3+1)+1))*($G11*(1+INDEX(Parametri!$E$31:$E$52,MATCH($B11,Parametri!$A$31:$A$52,0)))^(P$4-$H11)+$I11*(1+Parametri!$B$5)^(P$4-Parametri!$B$6)+IF(P$4=$F$3,$J11,0))) -> 60007.776 | Q11: =IF(Q$4<$F$3,0,MAX(0,MIN(1,$D11-(Q$4-$F$3+1)+1))*($G11*(1+INDEX(Parametri!$E$31:$E$52,MATCH($B11,Parametri!$A$31:$A$52,0)))^(Q$4-$H11)+$I11*(1+Parametri!$B$5)^(Q$4-Parametri!$B$6)+IF(Q$4=$F$3,$J11,0))) -> 61776.413 | R11: =IF(R$4<$F$3,0,MAX(0,MIN(1,$D11-(R$4-$F$3+1)+1))*($G11*(1+INDEX(Parametri!$E$31:$E$52,MATCH($B11,Parametri!$A$31:$A$52,0)))^(R$4-$H11)+$I11*(1+Parametri!$B$5)^(R$4-Parametri!$B$6)+IF(R$4=$F$3,$J11,0))) -> 0 | S11: =IF(S$4<$F$3,0,MAX(0,MIN(1,$D11-(S$4-$F$3+1)+1))*($G11*(1+INDEX(Parametri!$E$31:$E$52,MATCH($B11,Parametri!$A$31:$A$52,0)))^(S$4-$H11)+$I11*(1+Parametri!$B$5)^(S$4-Parametri!$B$6)+IF(S$4=$F$3,$J11,0))) -> 0 | T11: =$F11*N11 -> 447.10394 | U11: =$F11*O11 -> 413.86661 | V11: =$F11*P11 -> 426.06459 | W11: =$F11*Q11 -> 438.62218 | X11: =$F11*R11 -> 0 | Y11: =$F11*S11 -> 0 | Z11: Test IE/SAT ≥1200 + colloquio; benchmark Bachillerato 7,5+. Profilo A sopra i benchmark; tasso non ufficiale 30-40%.
A12: 7 | B12: ESCP — Bachelor in Management | C12: =INDEX(Parametri!$G$31:$G$52,MATCH($B12,Parametri!$A$31:$A$52,0)) -> ESCP (media 3 campus) | D12: =INDEX(Parametri!$D$31:$D$52,MATCH($B12,Parametri!$A$31:$A$52,0)) -> 3 | E12: 0.65 | F12: =E12*EXP(SUMPRODUCT(LN(1-$E$6:E11+($E$6:E11=1)*0.000000000001))) -> 0.0015383672 | G12: =INDEX(Parametri!$B$31:$B$52,MATCH($B12,Parametri!$A$31:$A$52,0)) -> 20800 | H12: =INDEX(Parametri!$C$31:$C$52,MATCH($B12,Parametri!$A$31:$A$52,0)) -> 2027 | I12: =INDEX(Parametri!$B$14:$B$27,MATCH($C12,Parametri!$A$14:$A$27,0)) -> 23000 | J12: =INDEX(Parametri!$F$31:$F$52,MATCH($B12,Parametri!$A$31:$A$52,0)) -> 80 | K12: =INDEX(N12:S12,MATCH($F$3,$N$4:$S$4,0)) -> 44570 | L12: =SUM(N12:S12) -> 137276.42 | M12: =F12*L12 -> 211.18154 | N12: =IF(N$4<$F$3,0,MAX(0,MIN(1,$D12-(N$4-$F$3+1)+1))*($G12*(1+INDEX(Parametri!$E$31:$E$52,MATCH($B12,Parametri!$A$31:$A$52,0)))^(N$4-$H12)+$I12*(1+Parametri!$B$5)^(N$4-Parametri!$B$6)+IF(N$4=$F$3,$J12,0))) -> 44570 | O12: =IF(O$4<$F$3,0,MAX(0,MIN(1,$D12-(O$4-$F$3+1)+1))*($G12*(1+INDEX(Parametri!$E$31:$E$52,MATCH($B12,Parametri!$A$31:$A$52,0)))^(O$4-$H12)+$I12*(1+Parametri!$B$5)^(O$4-Parametri!$B$6)+IF(O$4=$F$3,$J12,0))) -> 45720.7 | P12: =IF(P$4<$F$3,0,MAX(0,MIN(1,$D12-(P$4-$F$3+1)+1))*($G12*(1+INDEX(Parametri!$E$31:$E$52,MATCH($B12,Parametri!$A$31:$A$52,0)))^(P$4-$H12)+$I12*(1+Parametri!$B$5)^(P$4-Parametri!$B$6)+IF(P$4=$F$3,$J12,0))) -> 46985.721 | Q12: =IF(Q$4<$F$3,0,MAX(0,MIN(1,$D12-(Q$4-$F$3+1)+1))*($G12*(1+INDEX(Parametri!$E$31:$E$52,MATCH($B12,Parametri!$A$31:$A$52,0)))^(Q$4-$H12)+$I12*(1+Parametri!$B$5)^(Q$4-Parametri!$B$6)+IF(Q$4=$F$3,$J12,0))) -> 0 | R12: =IF(R$4<$F$3,0,MAX(0,MIN(1,$D12-(R$4-$F$3+1)+1))*($G12*(1+INDEX(Parametri!$E$31:$E$52,MATCH($B12,Parametri!$A$31:$A$52,0)))^(R$4-$H12)+$I12*(1+Parametri!$B$5)^(R$4-Parametri!$B$6)+IF(R$4=$F$3,$J12,0))) -> 0 | S12: =IF(S$4<$F$3,0,MAX(0,MIN(1,$D12-(S$4-$F$3+1)+1))*($G12*(1+INDEX(Parametri!$E$31:$E$52,MATCH($B12,Parametri!$A$31:$A$52,0)))^(S$4-$H12)+$I12*(1+Parametri!$B$5)^(S$4-Parametri!$B$6)+IF(S$4=$F$3,$J12,0))) -> 0 | T12: =$F12*N12 -> 68.565026 | U12: =$F12*O12 -> 70.335225 | V12: =$F12*P12 -> 72.281291 | W12: =$F12*Q12 -> 0 | X12: =$F12*R12 -> 0 | Y12: =$F12*S12 -> 0 | Z12: Valutazione olistica (transcript, statement, CV, C1, colloquio), nessun test obbligatorio; media 8,5 adeguata.
A13: 8 | B13: Forward College — Business & Management | C13: =INDEX(Parametri!$G$31:$G$52,MATCH($B13,Parametri!$A$31:$A$52,0)) -> Forward College (Lisbona/Parigi/Berlino) | D13: =INDEX(Parametri!$D$31:$D$52,MATCH($B13,Parametri!$A$31:$A$52,0)) -> 3 | E13: 0.55 | F13: =E13*EXP(SUMPRODUCT(LN(1-$E$6:E12+($E$6:E12=1)*0.000000000001))) -> 0.00045559336 | G13: =INDEX(Parametri!$B$31:$B$52,MATCH($B13,Parametri!$A$31:$A$52,0)) -> 21850 | H13: =INDEX(Parametri!$C$31:$C$52,MATCH($B13,Parametri!$A$31:$A$52,0)) -> 2027 | I13: =INDEX(Parametri!$B$14:$B$27,MATCH($C13,Parametri!$A$14:$A$27,0)) -> 21700 | J13: =INDEX(Parametri!$F$31:$F$52,MATCH($B13,Parametri!$A$31:$A$52,0)) -> 70 | K13: =INDEX(N13:S13,MATCH($F$3,$N$4:$S$4,0)) -> 44271 | L13: =SUM(N13:S13) -> 138036.83 | M13: =F13*L13 -> 62.888664 | N13: =IF(N$4<$F$3,0,MAX(0,MIN(1,$D13-(N$4-$F$3+1)+1))*($G13*(1+INDEX(Parametri!$E$31:$E$52,MATCH($B13,Parametri!$A$31:$A$52,0)))^(N$4-$H13)+$I13*(1+Parametri!$B$5)^(N$4-Parametri!$B$6)+IF(N$4=$F$3,$J13,0))) -> 44271 | O13: =IF(O$4<$F$3,0,MAX(0,MIN(1,$D13-(O$4-$F$3+1)+1))*($G13*(1+INDEX(Parametri!$E$31:$E$52,MATCH($B13,Parametri!$A$31:$A$52,0)))^(O$4-$H13)+$I13*(1+Parametri!$B$5)^(O$4-Parametri!$B$6)+IF(O$4=$F$3,$J13,0))) -> 45964.03 | P13: =IF(P$4<$F$3,0,MAX(0,MIN(1,$D13-(P$4-$F$3+1)+1))*($G13*(1+INDEX(Parametri!$E$31:$E$52,MATCH($B13,Parametri!$A$31:$A$52,0)))^(P$4-$H13)+$I13*(1+Parametri!$B$5)^(P$4-Parametri!$B$6)+IF(P$4=$F$3,$J13,0))) -> 47801.801 | Q13: =IF(Q$4<$F$3,0,MAX(0,MIN(1,$D13-(Q$4-$F$3+1)+1))*($G13*(1+INDEX(Parametri!$E$31:$E$52,MATCH($B13,Parametri!$A$31:$A$52,0)))^(Q$4-$H13)+$I13*(1+Parametri!$B$5)^(Q$4-Parametri!$B$6)+IF(Q$4=$F$3,$J13,0))) -> 0 | R13: =IF(R$4<$F$3,0,MAX(0,MIN(1,$D13-(R$4-$F$3+1)+1))*($G13*(1+INDEX(Parametri!$E$31:$E$52,MATCH($B13,Parametri!$A$31:$A$52,0)))^(R$4-$H13)+$I13*(1+Parametri!$B$5)^(R$4-Parametri!$B$6)+IF(R$4=$F$3,$J13,0))) -> 0 | S13: =IF(S$4<$F$3,0,MAX(0,MIN(1,$D13-(S$4-$F$3+1)+1))*($G13*(1+INDEX(Parametri!$E$31:$E$52,MATCH($B13,Parametri!$A$31:$A$52,0)))^(S$4-$H13)+$I13*(1+Parametri!$B$5)^(S$4-Parametri!$B$6)+IF(S$4=$F$3,$J13,0))) -> 0 | T13: =$F13*N13 -> 20.169574 | U13: =$F13*O13 -> 20.940907 | V13: =$F13*P13 -> 21.778183 | W13: =$F13*Q13 -> 0 | X13: =$F13*R13 -> 0 | Y13: =$F13*S13 -> 0 | Z13: Candidatura già inviata (sett. 2026); dichiarano ~1 su 8 offerte; dossier + colloquio 30'; requisito accademico UoL ≈ ABB.
A14: 9 | B14: Cattolica Milano — Economia | C14: =INDEX(Parametri!$G$31:$G$52,MATCH($B14,Parametri!$A$31:$A$52,0)) -> Milano (a casa) | D14: =INDEX(Parametri!$D$31:$D$52,MATCH($B14,Parametri!$A$31:$A$52,0)) -> 3 | E14: 1 | F14: =E14*EXP(SUMPRODUCT(LN(1-$E$6:E13+($E$6:E13=1)*0.000000000001))) -> 0.0003727582 | G14: =INDEX(Parametri!$B$31:$B$52,MATCH($B14,Parametri!$A$31:$A$52,0)) -> 11500 | H14: =INDEX(Parametri!$C$31:$C$52,MATCH($B14,Parametri!$A$31:$A$52,0)) -> 2026 | I14: =INDEX(Parametri!$B$14:$B$27,MATCH($C14,Parametri!$A$14:$A$27,0)) -> 2800 | J14: =INDEX(Parametri!$F$31:$F$52,MATCH($B14,Parametri!$A$31:$A$52,0)) -> 0 | K14: =INDEX(N14:S14,MATCH($F$3,$N$4:$S$4,0)) -> 14671.5 | L14: =SUM(N14:S14) -> 45168.085 | M14: =F14*L14 -> 16.836774 | N14: =IF(N$4<$F$3,0,MAX(0,MIN(1,$D14-(N$4-$F$3+1)+1))*($G14*(1+INDEX(Parametri!$E$31:$E$52,MATCH($B14,Parametri!$A$31:$A$52,0)))^(N$4-$H14)+$I14*(1+Parametri!$B$5)^(N$4-Parametri!$B$6)+IF(N$4=$F$3,$J14,0))) -> 14671.5 | O14: =IF(O$4<$F$3,0,MAX(0,MIN(1,$D14-(O$4-$F$3+1)+1))*($G14*(1+INDEX(Parametri!$E$31:$E$52,MATCH($B14,Parametri!$A$31:$A$52,0)))^(O$4-$H14)+$I14*(1+Parametri!$B$5)^(O$4-Parametri!$B$6)+IF(O$4=$F$3,$J14,0))) -> 15052.708 | P14: =IF(P$4<$F$3,0,MAX(0,MIN(1,$D14-(P$4-$F$3+1)+1))*($G14*(1+INDEX(Parametri!$E$31:$E$52,MATCH($B14,Parametri!$A$31:$A$52,0)))^(P$4-$H14)+$I14*(1+Parametri!$B$5)^(P$4-Parametri!$B$6)+IF(P$4=$F$3,$J14,0))) -> 15443.878 | Q14: =IF(Q$4<$F$3,0,MAX(0,MIN(1,$D14-(Q$4-$F$3+1)+1))*($G14*(1+INDEX(Parametri!$E$31:$E$52,MATCH($B14,Parametri!$A$31:$A$52,0)))^(Q$4-$H14)+$I14*(1+Parametri!$B$5)^(Q$4-Parametri!$B$6)+IF(Q$4=$F$3,$J14,0))) -> 0 | R14: =IF(R$4<$F$3,0,MAX(0,MIN(1,$D14-(R$4-$F$3+1)+1))*($G14*(1+INDEX(Parametri!$E$31:$E$52,MATCH($B14,Parametri!$A$31:$A$52,0)))^(R$4-$H14)+$I14*(1+Parametri!$B$5)^(R$4-Parametri!$B$6)+IF(R$4=$F$3,$J14,0))) -> 0 | S14: =IF(S$4<$F$3,0,MAX(0,MIN(1,$D14-(S$4-$F$3+1)+1))*($G14*(1+INDEX(Parametri!$E$31:$E$52,MATCH($B14,Parametri!$A$31:$A$52,0)))^(S$4-$H14)+$I14*(1+Parametri!$B$5)^(S$4-Parametri!$B$6)+IF(S$4=$F$3,$J14,0))) -> 0 | T14: =$F14*N14 -> 5.468922 | U14: =$F14*O14 -> 5.6110202 | V14: =$F14*P14 -> 5.7568321 | W14: =$F14*Q14 -> 0 | X14: =$F14*R14 -> 0 | Y14: =$F14*S14 -> 0 | Z14: Ripiego a Milano: ammissione pressoché certa.
B15: TOTALE / ATTESO | F15: =SUM(F6:F14) -> 1 | M15: =SUM(M6:M14) -> 103764.87 | T15: =SUM(T6:T14) -> 30865.987 | U15: =SUM(U6:U14) -> 31690.489 | V15: =SUM(V6:V14) -> 32615.243 | W15: =SUM(W6:W14) -> 8593.1564 | X15: =SUM(X6:X14) -> 0 | Y15: =SUM(Y6:Y14) -> 0 | Z15: P(iscrizione) deve sommare a 100%
B17: Scenario più probabile (max P(iscrizione)) | C17: =INDEX($B$6:$B$14,MATCH(MAX($F$6:$F$14),$F$6:$F$14,0)) -> Rotterdam EUR — IBEB | L17: =INDEX($L$6:$L$14,MATCH(MAX($F$6:$F$14),$F$6:$F$14,0)) -> 102583.41 | N17: =INDEX($N$6:$N$14,MATCH(MAX($F$6:$F$14),$F$6:$F$14,0)) -> 29551 | O17: =INDEX($O$6:$O$14,MATCH(MAX($F$6:$F$14),$F$6:$F$14,0)) -> 30423.675 | P17: =INDEX($P$6:$P$14,MATCH(MAX($F$6:$F$14),$F$6:$F$14,0)) -> 31322.184 | Q17: =INDEX($Q$6:$Q$14,MATCH(MAX($F$6:$F$14),$F$6:$F$14,0)) -> 11286.553 | R17: =INDEX($R$6:$R$14,MATCH(MAX($F$6:$F$14),$F$6:$F$14,0)) -> 0 | S17: =INDEX($S$6:$S$14,MATCH(MAX($F$6:$F$14),$F$6:$F$14,0)) -> 0
B18: Scenario economico (min costo tra opzioni con P ≥ soglia) | C18: =INDEX($B$6:$B$14,MATCH(_xlfn.MINIFS($L$6:$L$14,$F$6:$F$14,">="&Parametri!$B$10),$L$6:$L$14,0)) -> CBS Copenhagen — BSc (IB / BADM / BASM) | L18: =INDEX($L$6:$L$14,MATCH(_xlfn.MINIFS($L$6:$L$14,$F$6:$F$14,">="&Parametri!$B$10),$L$6:$L$14,0)) -> 76907.048 | N18: =INDEX($N$6:$N$14,MATCH(_xlfn.MINIFS($L$6:$L$14,$F$6:$F$14,">="&Parametri!$B$10),$L$6:$L$14,0)) -> 25220 | O18: =INDEX($O$6:$O$14,MATCH(_xlfn.MINIFS($L$6:$L$14,$F$6:$F$14,">="&Parametri!$B$10),$L$6:$L$14,0)) -> 25461.6 | P18: =INDEX($P$6:$P$14,MATCH(_xlfn.MINIFS($L$6:$L$14,$F$6:$F$14,">="&Parametri!$B$10),$L$6:$L$14,0)) -> 26225.448 | Q18: =INDEX($Q$6:$Q$14,MATCH(_xlfn.MINIFS($L$6:$L$14,$F$6:$F$14,">="&Parametri!$B$10),$L$6:$L$14,0)) -> 0 | R18: =INDEX($R$6:$R$14,MATCH(_xlfn.MINIFS($L$6:$L$14,$F$6:$F$14,">="&Parametri!$B$10),$L$6:$L$14,0)) -> 0 | S18: =INDEX($S$6:$S$14,MATCH(_xlfn.MINIFS($L$6:$L$14,$F$6:$F$14,">="&Parametri!$B$10),$L$6:$L$14,0)) -> 0
B19: Scenario caro (max costo tra opzioni con P ≥ soglia) | C19: =INDEX($B$6:$B$14,MATCH(_xlfn.MAXIFS($L$6:$L$14,$F$6:$F$14,">="&Parametri!$B$10),$L$6:$L$14,0)) -> Sciences Po — Bachelor Collège universitaire | L19: =INDEX($L$6:$L$14,MATCH(_xlfn.MAXIFS($L$6:$L$14,$F$6:$F$14,">="&Parametri!$B$10),$L$6:$L$14,0)) -> 123379.53 | N19: =INDEX($N$6:$N$14,MATCH(_xlfn.MAXIFS($L$6:$L$14,$F$6:$F$14,">="&Parametri!$B$10),$L$6:$L$14,0)) -> 39992.5 | O19: =INDEX($O$6:$O$14,MATCH(_xlfn.MAXIFS($L$6:$L$14,$F$6:$F$14,">="&Parametri!$B$10),$L$6:$L$14,0)) -> 41115.912 | P19: =INDEX($P$6:$P$14,MATCH(_xlfn.MAXIFS($L$6:$L$14,$F$6:$F$14,">="&Parametri!$B$10),$L$6:$L$14,0)) -> 42271.118 | Q19: =INDEX($Q$6:$Q$14,MATCH(_xlfn.MAXIFS($L$6:$L$14,$F$6:$F$14,">="&Parametri!$B$10),$L$6:$L$14,0)) -> 0 | R19: =INDEX($R$6:$R$14,MATCH(_xlfn.MAXIFS($L$6:$L$14,$F$6:$F$14,">="&Parametri!$B$10),$L$6:$L$14,0)) -> 0 | S19: =INDEX($S$6:$S$14,MATCH(_xlfn.MAXIFS($L$6:$L$14,$F$6:$F$14,">="&Parametri!$B$10),$L$6:$L$14,0)) -> 0

Sheet Marco
A1: MARCO — cascata di opzioni, probabilità e costi
A2: Profilo: liceo scientifico quinquennale, 4ª nel 2026/27, media obiettivo 7,5 (poco meno di 7 in 3ª), inglese B2 (potenziale C1), matematica da portare verso l'8. Preferisce l'estero in città vere; Bocconi gradita. Candidatura Rotterdam già decisa (IBA).
A3: Anno di ingresso (a.a. che inizia a settembre): | F3: =Parametri!$B$8 -> 2028 | G3: ← da Parametri | N3: Costo annuo nominale dell'opzione (non ponderato) | T3: Esborso atteso = P(iscrizione) × costo
N4: 2027 | O4: 2028 | P4: 2029 | Q4: 2030 | R4: 2031 | S4: 2032 | T4: 2027 | U4: 2028 | V4: 2029 | W4: 2030 | X4: 2031 | Y4: 2032
A5: # | B5: Opzione (chiave in Parametri) | C5: Città | D5: Anni | E5: P(ammiss.) | F5: P(iscriz.) | G5: Retta base € | H5: Anno base | I5: Mantenim. base € | J5: Una tantum € | K5: Costo 1° anno € | L5: Costo totale percorso € | M5: Costo atteso € | N5: Costo 2027/28 | O5: Costo 2028/29 | P5: Costo 2029/30 | Q5: Costo 2030/31 | R5: Costo 2031/32 | S5: Costo 2032/33 | T5: Atteso 2027/28 | U5: Atteso 2028/29 | V5: Atteso 2029/30 | W5: Atteso 2030/31 | X5: Atteso 2031/32 | Y5: Atteso 2032/33 | Z5: Motivazione della probabilità
A6: 1 | B6: Rotterdam RSM — IBA | C6: =INDEX(Parametri!$G$31:$G$52,MATCH($B6,Parametri!$A$31:$A$52,0)) -> Rotterdam | D6: =INDEX(Parametri!$D$31:$D$52,MATCH($B6,Parametri!$A$31:$A$52,0)) -> 3 | E6: 0.45 | F6: =E6 -> 0.45 | G6: =INDEX(Parametri!$B$31:$B$52,MATCH($B6,Parametri!$A$31:$A$52,0)) -> 2771 | H6: =INDEX(Parametri!$C$31:$C$52,MATCH($B6,Parametri!$A$31:$A$52,0)) -> 2027 | I6: =INDEX(Parametri!$B$14:$B$27,MATCH($C6,Parametri!$A$14:$A$27,0)) -> 26000 | J6: =INDEX(Parametri!$F$31:$F$52,MATCH($B6,Parametri!$A$31:$A$52,0)) -> 0 | K6: =INDEX(N6:S6,MATCH($F$3,$N$4:$S$4,0)) -> 30423.675 | L6: =SUM(N6:S6) -> 93993.152 | M6: =F6*L6 -> 42296.918 | N6: =IF(N$4<$F$3,0,MAX(0,MIN(1,$D6-(N$4-$F$3+1)+1))*($G6*(1+INDEX(Parametri!$E$31:$E$52,MATCH($B6,Parametri!$A$31:$A$52,0)))^(N$4-$H6)+$I6*(1+Parametri!$B$5)^(N$4-Parametri!$B$6)+IF(N$4=$F$3,$J6,0))) -> 0 | O6: =IF(O$4<$F$3,0,MAX(0,MIN(1,$D6-(O$4-$F$3+1)+1))*($G6*(1+INDEX(Parametri!$E$31:$E$52,MATCH($B6,Parametri!$A$31:$A$52,0)))^(O$4-$H6)+$I6*(1+Parametri!$B$5)^(O$4-Parametri!$B$6)+IF(O$4=$F$3,$J6,0))) -> 30423.675 | P6: =IF(P$4<$F$3,0,MAX(0,MIN(1,$D6-(P$4-$F$3+1)+1))*($G6*(1+INDEX(Parametri!$E$31:$E$52,MATCH($B6,Parametri!$A$31:$A$52,0)))^(P$4-$H6)+$I6*(1+Parametri!$B$5)^(P$4-Parametri!$B$6)+IF(P$4=$F$3,$J6,0))) -> 31322.184 | Q6: =IF(Q$4<$F$3,0,MAX(0,MIN(1,$D6-(Q$4-$F$3+1)+1))*($G6*(1+INDEX(Parametri!$E$31:$E$52,MATCH($B6,Parametri!$A$31:$A$52,0)))^(Q$4-$H6)+$I6*(1+Parametri!$B$5)^(Q$4-Parametri!$B$6)+IF(Q$4=$F$3,$J6,0))) -> 32247.293 | R6: =IF(R$4<$F$3,0,MAX(0,MIN(1,$D6-(R$4-$F$3+1)+1))*($G6*(1+INDEX(Parametri!$E$31:$E$52,MATCH($B6,Parametri!$A$31:$A$52,0)))^(R$4-$H6)+$I6*(1+Parametri!$B$5)^(R$4-Parametri!$B$6)+IF(R$4=$F$3,$J6,0))) -> 0 | S6: =IF(S$4<$F$3,0,MAX(0,MIN(1,$D6-(S$4-$F$3+1)+1))*($G6*(1+INDEX(Parametri!$E$31:$E$52,MATCH($B6,Parametri!$A$31:$A$52,0)))^(S$4-$H6)+$I6*(1+Parametri!$B$5)^(S$4-Parametri!$B$6)+IF(S$4=$F$3,$J6,0))) -> 0 | T6: =$F6*N6 -> 0 | U6: =$F6*O6 -> 13690.654 | V6: =$F6*P6 -> 14094.983 | W6: =$F6*Q6 -> 14511.282 | X6: =$F6*R6 -> 0 | Y6: =$F6*S6 -> 0 | Z6: Numerus fixus 650 posti, ranking 75% media (non arrotondata) + 25% motivazione; ultimo ammesso ~1.280° con liste d'attesa. Media 7-7,5 converte vicino alla soglia 6,5 NL: 50/50, motivazione decisiva.
A7: 2 | B7: Bocconi — CLEAM/Management/BIEM | C7: =INDEX(Parametri!$G$31:$G$52,MATCH($B7,Parametri!$A$31:$A$52,0)) -> Milano (a casa) | D7: =INDEX(Parametri!$D$31:$D$52,MATCH($B7,Parametri!$A$31:$A$52,0)) -> 3 | E7: 0.25 | F7: =E7*EXP(SUMPRODUCT(LN(1-$E$6:E6+($E$6:E6=1)*0.000000000001))) -> 0.1375 | G7: =INDEX(Parametri!$B$31:$B$52,MATCH($B7,Parametri!$A$31:$A$52,0)) -> 17000 | H7: =INDEX(Parametri!$C$31:$C$52,MATCH($B7,Parametri!$A$31:$A$52,0)) -> 2026 | I7: =INDEX(Parametri!$B$14:$B$27,MATCH($C7,Parametri!$A$14:$A$27,0)) -> 2800 | J7: =INDEX(Parametri!$F$31:$F$52,MATCH($B7,Parametri!$A$31:$A$52,0)) -> 0 | K7: =INDEX(N7:S7,MATCH($F$3,$N$4:$S$4,0)) -> 20831.145 | L7: =SUM(N7:S7) -> 64114.165 | M7: =F7*L7 -> 8815.6977 | N7: =IF(N$4<$F$3,0,MAX(0,MIN(1,$D7-(N$4-$F$3+1)+1))*($G7*(1+INDEX(Parametri!$E$31:$E$52,MATCH($B7,Parametri!$A$31:$A$52,0)))^(N$4-$H7)+$I7*(1+Parametri!$B$5)^(N$4-Parametri!$B$6)+IF(N$4=$F$3,$J7,0))) -> 0 | O7: =IF(O$4<$F$3,0,MAX(0,MIN(1,$D7-(O$4-$F$3+1)+1))*($G7*(1+INDEX(Parametri!$E$31:$E$52,MATCH($B7,Parametri!$A$31:$A$52,0)))^(O$4-$H7)+$I7*(1+Parametri!$B$5)^(O$4-Parametri!$B$6)+IF(O$4=$F$3,$J7,0))) -> 20831.145 | P7: =IF(P$4<$F$3,0,MAX(0,MIN(1,$D7-(P$4-$F$3+1)+1))*($G7*(1+INDEX(Parametri!$E$31:$E$52,MATCH($B7,Parametri!$A$31:$A$52,0)))^(P$4-$H7)+$I7*(1+Parametri!$B$5)^(P$4-Parametri!$B$6)+IF(P$4=$F$3,$J7,0))) -> 21366.776 | Q7: =IF(Q$4<$F$3,0,MAX(0,MIN(1,$D7-(Q$4-$F$3+1)+1))*($G7*(1+INDEX(Parametri!$E$31:$E$52,MATCH($B7,Parametri!$A$31:$A$52,0)))^(Q$4-$H7)+$I7*(1+Parametri!$B$5)^(Q$4-Parametri!$B$6)+IF(Q$4=$F$3,$J7,0))) -> 21916.244 | R7: =IF(R$4<$F$3,0,MAX(0,MIN(1,$D7-(R$4-$F$3+1)+1))*($G7*(1+INDEX(Parametri!$E$31:$E$52,MATCH($B7,Parametri!$A$31:$A$52,0)))^(R$4-$H7)+$I7*(1+Parametri!$B$5)^(R$4-Parametri!$B$6)+IF(R$4=$F$3,$J7,0))) -> 0 | S7: =IF(S$4<$F$3,0,MAX(0,MIN(1,$D7-(S$4-$F$3+1)+1))*($G7*(1+INDEX(Parametri!$E$31:$E$52,MATCH($B7,Parametri!$A$31:$A$52,0)))^(S$4-$H7)+$I7*(1+Parametri!$B$5)^(S$4-Parametri!$B$6)+IF(S$4=$F$3,$J7,0))) -> 0 | T7: =$F7*N7 -> 0 | U7: =$F7*O7 -> 2864.2824 | V7: =$F7*P7 -> 2937.9317 | W7: =$F7*Q7 -> 3013.4835 | X7: =$F7*R7 -> 0 | Y7: =$F7*S7 -> 0 | Z7: Con media 7-7,5 (3ª e 4ª) serve un test ≥35/50: possibile ma non probabile. Solo corsi in italiano (CLEAM/Management).
A8: 3 | B8: ESADE Barcellona — BBA / GGELO | C8: =INDEX(Parametri!$G$31:$G$52,MATCH($B8,Parametri!$A$31:$A$52,0)) -> Barcellona | D8: =INDEX(Parametri!$D$31:$D$52,MATCH($B8,Parametri!$A$31:$A$52,0)) -> 4 | E8: 0.45 | F8: =E8*EXP(SUMPRODUCT(LN(1-$E$6:E7+($E$6:E7=1)*0.000000000001))) -> 0.185625 | G8: =INDEX(Parametri!$B$31:$B$52,MATCH($B8,Parametri!$A$31:$A$52,0)) -> 21300 | H8: =INDEX(Parametri!$C$31:$C$52,MATCH($B8,Parametri!$A$31:$A$52,0)) -> 2027 | I8: =INDEX(Parametri!$B$14:$B$27,MATCH($C8,Parametri!$A$14:$A$27,0)) -> 27000 | J8: =INDEX(Parametri!$F$31:$F$52,MATCH($B8,Parametri!$A$31:$A$52,0)) -> 0 | K8: =INDEX(N8:S8,MATCH($F$3,$N$4:$S$4,0)) -> 50476.8 | L8: =SUM(N8:S8) -> 210496.86 | M8: =F8*L8 -> 39073.48 | N8: =IF(N$4<$F$3,0,MAX(0,MIN(1,$D8-(N$4-$F$3+1)+1))*($G8*(1+INDEX(Parametri!$E$31:$E$52,MATCH($B8,Parametri!$A$31:$A$52,0)))^(N$4-$H8)+$I8*(1+Parametri!$B$5)^(N$4-Parametri!$B$6)+IF(N$4=$F$3,$J8,0))) -> 0 | O8: =IF(O$4<$F$3,0,MAX(0,MIN(1,$D8-(O$4-$F$3+1)+1))*($G8*(1+INDEX(Parametri!$E$31:$E$52,MATCH($B8,Parametri!$A$31:$A$52,0)))^(O$4-$H8)+$I8*(1+Parametri!$B$5)^(O$4-Parametri!$B$6)+IF(O$4=$F$3,$J8,0))) -> 50476.8 | P8: =IF(P$4<$F$3,0,MAX(0,MIN(1,$D8-(P$4-$F$3+1)+1))*($G8*(1+INDEX(Parametri!$E$31:$E$52,MATCH($B8,Parametri!$A$31:$A$52,0)))^(P$4-$H8)+$I8*(1+Parametri!$B$5)^(P$4-Parametri!$B$6)+IF(P$4=$F$3,$J8,0))) -> 51881.942 | Q8: =IF(Q$4<$F$3,0,MAX(0,MIN(1,$D8-(Q$4-$F$3+1)+1))*($G8*(1+INDEX(Parametri!$E$31:$E$52,MATCH($B8,Parametri!$A$31:$A$52,0)))^(Q$4-$H8)+$I8*(1+Parametri!$B$5)^(Q$4-Parametri!$B$6)+IF(Q$4=$F$3,$J8,0))) -> 53326.508 | R8: =IF(R$4<$F$3,0,MAX(0,MIN(1,$D8-(R$4-$F$3+1)+1))*($G8*(1+INDEX(Parametri!$E$31:$E$52,MATCH($B8,Parametri!$A$31:$A$52,0)))^(R$4-$H8)+$I8*(1+Parametri!$B$5)^(R$4-Parametri!$B$6)+IF(R$4=$F$3,$J8,0))) -> 54811.615 | S8: =IF(S$4<$F$3,0,MAX(0,MIN(1,$D8-(S$4-$F$3+1)+1))*($G8*(1+INDEX(Parametri!$E$31:$E$52,MATCH($B8,Parametri!$A$31:$A$52,0)))^(S$4-$H8)+$I8*(1+Parametri!$B$5)^(S$4-Parametri!$B$6)+IF(S$4=$F$3,$J8,0))) -> 0 | T8: =$F8*N8 -> 0 | U8: =$F8*O8 -> 9369.756 | V8: =$F8*P8 -> 9630.5854 | W8: =$F8*Q8 -> 9898.7331 | X8: =$F8*R8 -> 10174.406 | Y8: =$F8*S8 -> 0 | Z8: Test ESADE/SAT + transcript 3 anni a pari peso; benchmark IB 34+. Media 7,5 sotto i benchmark, compensabile con test forte.
A9: 4 | B9: Maastricht SBE — International Business | C9: =INDEX(Parametri!$G$31:$G$52,MATCH($B9,Parametri!$A$31:$A$52,0)) -> Maastricht | D9: =INDEX(Parametri!$D$31:$D$52,MATCH($B9,Parametri!$A$31:$A$52,0)) -> 3 | E9: 0.65 | F9: =E9*EXP(SUMPRODUCT(LN(1-$E$6:E8+($E$6:E8=1)*0.000000000001))) -> 0.14746875 | G9: =INDEX(Parametri!$B$31:$B$52,MATCH($B9,Parametri!$A$31:$A$52,0)) -> 2771 | H9: =INDEX(Parametri!$C$31:$C$52,MATCH($B9,Parametri!$A$31:$A$52,0)) -> 2027 | I9: =INDEX(Parametri!$B$14:$B$27,MATCH($C9,Parametri!$A$14:$A$27,0)) -> 23500 | J9: =INDEX(Parametri!$F$31:$F$52,MATCH($B9,Parametri!$A$31:$A$52,0)) -> 0 | K9: =INDEX(N9:S9,MATCH($F$3,$N$4:$S$4,0)) -> 27771.425 | L9: =SUM(N9:S9) -> 85795.312 | M9: =F9*L9 -> 12652.127 | N9: =IF(N$4<$F$3,0,MAX(0,MIN(1,$D9-(N$4-$F$3+1)+1))*($G9*(1+INDEX(Parametri!$E$31:$E$52,MATCH($B9,Parametri!$A$31:$A$52,0)))^(N$4-$H9)+$I9*(1+Parametri!$B$5)^(N$4-Parametri!$B$6)+IF(N$4=$F$3,$J9,0))) -> 0 | O9: =IF(O$4<$F$3,0,MAX(0,MIN(1,$D9-(O$4-$F$3+1)+1))*($G9*(1+INDEX(Parametri!$E$31:$E$52,MATCH($B9,Parametri!$A$31:$A$52,0)))^(O$4-$H9)+$I9*(1+Parametri!$B$5)^(O$4-Parametri!$B$6)+IF(O$4=$F$3,$J9,0))) -> 27771.425 | P9: =IF(P$4<$F$3,0,MAX(0,MIN(1,$D9-(P$4-$F$3+1)+1))*($G9*(1+INDEX(Parametri!$E$31:$E$52,MATCH($B9,Parametri!$A$31:$A$52,0)))^(P$4-$H9)+$I9*(1+Parametri!$B$5)^(P$4-Parametri!$B$6)+IF(P$4=$F$3,$J9,0))) -> 28590.366 | Q9: =IF(Q$4<$F$3,0,MAX(0,MIN(1,$D9-(Q$4-$F$3+1)+1))*($G9*(1+INDEX(Parametri!$E$31:$E$52,MATCH($B9,Parametri!$A$31:$A$52,0)))^(Q$4-$H9)+$I9*(1+Parametri!$B$5)^(Q$4-Parametri!$B$6)+IF(Q$4=$F$3,$J9,0))) -> 29433.521 | R9: =IF(R$4<$F$3,0,MAX(0,MIN(1,$D9-(R$4-$F$3+1)+1))*($G9*(1+INDEX(Parametri!$E$31:$E$52,MATCH($B9,Parametri!$A$31:$A$52,0)))^(R$4-$H9)+$I9*(1+Parametri!$B$5)^(R$4-Parametri!$B$6)+IF(R$4=$F$3,$J9,0))) -> 0 | S9: =IF(S$4<$F$3,0,MAX(0,MIN(1,$D9-(S$4-$F$3+1)+1))*($G9*(1+INDEX(Parametri!$E$31:$E$52,MATCH($B9,Parametri!$A$31:$A$52,0)))^(S$4-$H9)+$I9*(1+Parametri!$B$5)^(S$4-Parametri!$B$6)+IF(S$4=$F$3,$J9,0))) -> 0 | T9: =$F9*N9 -> 0 | U9: =$F9*O9 -> 4095.4173 | V9: =$F9*P9 -> 4216.1856 | W9: =$F9*Q9 -> 4340.5245 | X9: =$F9*R9 -> 0 | Y9: =$F9*S9 -> 0 | Z9: Selezione 1/3 essay, 1/3 CV, 1/3 voti penultimo anno (mate 50%); ~67% dei candidati selezionati.
A10: 5 | B10: UvA Amsterdam — Economics & Business Economics | C10: =INDEX(Parametri!$G$31:$G$52,MATCH($B10,Parametri!$A$31:$A$52,0)) -> Amsterdam | D10: =INDEX(Parametri!$D$31:$D$52,MATCH($B10,Parametri!$A$31:$A$52,0)) -> 3 | E10: 0.85 | F10: =E10*EXP(SUMPRODUCT(LN(1-$E$6:E9+($E$6:E9=1)*0.000000000001))) -> 0.067495313 | G10: =INDEX(Parametri!$B$31:$B$52,MATCH($B10,Parametri!$A$31:$A$52,0)) -> 2771 | H10: =INDEX(Parametri!$C$31:$C$52,MATCH($B10,Parametri!$A$31:$A$52,0)) -> 2027 | I10: =INDEX(Parametri!$B$14:$B$27,MATCH($C10,Parametri!$A$14:$A$27,0)) -> 30000 | J10: =INDEX(Parametri!$F$31:$F$52,MATCH($B10,Parametri!$A$31:$A$52,0)) -> 0 | K10: =INDEX(N10:S10,MATCH($F$3,$N$4:$S$4,0)) -> 34667.275 | L10: =SUM(N10:S10) -> 107109.7 | M10: =F10*L10 -> 7229.4023 | N10: =IF(N$4<$F$3,0,MAX(0,MIN(1,$D10-(N$4-$F$3+1)+1))*($G10*(1+INDEX(Parametri!$E$31:$E$52,MATCH($B10,Parametri!$A$31:$A$52,0)))^(N$4-$H10)+$I10*(1+Parametri!$B$5)^(N$4-Parametri!$B$6)+IF(N$4=$F$3,$J10,0))) -> 0 | O10: =IF(O$4<$F$3,0,MAX(0,MIN(1,$D10-(O$4-$F$3+1)+1))*($G10*(1+INDEX(Parametri!$E$31:$E$52,MATCH($B10,Parametri!$A$31:$A$52,0)))^(O$4-$H10)+$I10*(1+Parametri!$B$5)^(O$4-Parametri!$B$6)+IF(O$4=$F$3,$J10,0))) -> 34667.275 | P10: =IF(P$4<$F$3,0,MAX(0,MIN(1,$D10-(P$4-$F$3+1)+1))*($G10*(1+INDEX(Parametri!$E$31:$E$52,MATCH($B10,Parametri!$A$31:$A$52,0)))^(P$4-$H10)+$I10*(1+Parametri!$B$5)^(P$4-Parametri!$B$6)+IF(P$4=$F$3,$J10,0))) -> 35693.092 | Q10: =IF(Q$4<$F$3,0,MAX(0,MIN(1,$D10-(Q$4-$F$3+1)+1))*($G10*(1+INDEX(Parametri!$E$31:$E$52,MATCH($B10,Parametri!$A$31:$A$52,0)))^(Q$4-$H10)+$I10*(1+Parametri!$B$5)^(Q$4-Parametri!$B$6)+IF(Q$4=$F$3,$J10,0))) -> 36749.328 | R10: =IF(R$4<$F$3,0,MAX(0,MIN(1,$D10-(R$4-$F$3+1)+1))*($G10*(1+INDEX(Parametri!$E$31:$E$52,MATCH($B10,Parametri!$A$31:$A$52,0)))^(R$4-$H10)+$I10*(1+Parametri!$B$5)^(R$4-Parametri!$B$6)+IF(R$4=$F$3,$J10,0))) -> 0 | S10: =IF(S$4<$F$3,0,MAX(0,MIN(1,$D10-(S$4-$F$3+1)+1))*($G10*(1+INDEX(Parametri!$E$31:$E$52,MATCH($B10,Parametri!$A$31:$A$52,0)))^(S$4-$H10)+$I10*(1+Parametri!$B$5)^(S$4-Parametri!$B$6)+IF(S$4=$F$3,$J10,0))) -> 0 | T10: =$F10*N10 -> 0 | U10: =$F10*O10 -> 2339.8786 | V10: =$F10*P10 -> 2409.1164 | W10: =$F10*Q10 -> 2480.4074 | X10: =$F10*R10 -> 0 | Y10: =$F10*S10 -> 0 | Z10: Numerus fixus con solo test online: nel 2026 offerte fino al 1.487° su ~1.500 partecipanti; richiesti diploma scientifico e matematica sufficiente.
A11: 6 | B11: Tilburg — Economics / IBA | C11: =INDEX(Parametri!$G$31:$G$52,MATCH($B11,Parametri!$A$31:$A$52,0)) -> Tilburg | D11: =INDEX(Parametri!$D$31:$D$52,MATCH($B11,Parametri!$A$31:$A$52,0)) -> 3 | E11: 0.9 | F11: =E11*EXP(SUMPRODUCT(LN(1-$E$6:E10+($E$6:E10=1)*0.000000000001))) -> 0.010719844 | G11: =INDEX(Parametri!$B$31:$B$52,MATCH($B11,Parametri!$A$31:$A$52,0)) -> 2771 | H11: =INDEX(Parametri!$C$31:$C$52,MATCH($B11,Parametri!$A$31:$A$52,0)) -> 2027 | I11: =INDEX(Parametri!$B$14:$B$27,MATCH($C11,Parametri!$A$14:$A$27,0)) -> 23000 | J11: =INDEX(Parametri!$F$31:$F$52,MATCH($B11,Parametri!$A$31:$A$52,0)) -> 0 | K11: =INDEX(N11:S11,MATCH($F$3,$N$4:$S$4,0)) -> 27240.975 | L11: =SUM(N11:S11) -> 84155.744 | M11: =F11*L11 -> 902.13643 | N11: =IF(N$4<$F$3,0,MAX(0,MIN(1,$D11-(N$4-$F$3+1)+1))*($G11*(1+INDEX(Parametri!$E$31:$E$52,MATCH($B11,Parametri!$A$31:$A$52,0)))^(N$4-$H11)+$I11*(1+Parametri!$B$5)^(N$4-Parametri!$B$6)+IF(N$4=$F$3,$J11,0))) -> 0 | O11: =IF(O$4<$F$3,0,MAX(0,MIN(1,$D11-(O$4-$F$3+1)+1))*($G11*(1+INDEX(Parametri!$E$31:$E$52,MATCH($B11,Parametri!$A$31:$A$52,0)))^(O$4-$H11)+$I11*(1+Parametri!$B$5)^(O$4-Parametri!$B$6)+IF(O$4=$F$3,$J11,0))) -> 27240.975 | P11: =IF(P$4<$F$3,0,MAX(0,MIN(1,$D11-(P$4-$F$3+1)+1))*($G11*(1+INDEX(Parametri!$E$31:$E$52,MATCH($B11,Parametri!$A$31:$A$52,0)))^(P$4-$H11)+$I11*(1+Parametri!$B$5)^(P$4-Parametri!$B$6)+IF(P$4=$F$3,$J11,0))) -> 28044.003 | Q11: =IF(Q$4<$F$3,0,MAX(0,MIN(1,$D11-(Q$4-$F$3+1)+1))*($G11*(1+INDEX(Parametri!$E$31:$E$52,MATCH($B11,Parametri!$A$31:$A$52,0)))^(Q$4-$H11)+$I11*(1+Parametri!$B$5)^(Q$4-Parametri!$B$6)+IF(Q$4=$F$3,$J11,0))) -> 28870.767 | R11: =IF(R$4<$F$3,0,MAX(0,MIN(1,$D11-(R$4-$F$3+1)+1))*($G11*(1+INDEX(Parametri!$E$31:$E$52,MATCH($B11,Parametri!$A$31:$A$52,0)))^(R$4-$H11)+$I11*(1+Parametri!$B$5)^(R$4-Parametri!$B$6)+IF(R$4=$F$3,$J11,0))) -> 0 | S11: =IF(S$4<$F$3,0,MAX(0,MIN(1,$D11-(S$4-$F$3+1)+1))*($G11*(1+INDEX(Parametri!$E$31:$E$52,MATCH($B11,Parametri!$A$31:$A$52,0)))^(S$4-$H11)+$I11*(1+Parametri!$B$5)^(S$4-Parametri!$B$6)+IF(S$4=$F$3,$J11,0))) -> 0 | T11: =$F11*N11 -> 0 | U11: =$F11*O11 -> 292.019 | V11: =$F11*P11 -> 300.62733 | W11: =$F11*Q11 -> 309.49011 | X11: =$F11*R11 -> 0 | Y11: =$F11*S11 -> 0 | Z11: Solo requisiti (matematica all'esame finale, IELTS 6.0) + matching.
A12: 7 | B12: Cattolica Milano — Economia | C12: =INDEX(Parametri!$G$31:$G$52,MATCH($B12,Parametri!$A$31:$A$52,0)) -> Milano (a casa) | D12: =INDEX(Parametri!$D$31:$D$52,MATCH($B12,Parametri!$A$31:$A$52,0)) -> 3 | E12: 1 | F12: =E12*EXP(SUMPRODUCT(LN(1-$E$6:E11+($E$6:E11=1)*0.000000000001))) -> 0.0011910938 | G12: =INDEX(Parametri!$B$31:$B$52,MATCH($B12,Parametri!$A$31:$A$52,0)) -> 11500 | H12: =INDEX(Parametri!$C$31:$C$52,MATCH($B12,Parametri!$A$31:$A$52,0)) -> 2026 | I12: =INDEX(Parametri!$B$14:$B$27,MATCH($C12,Parametri!$A$14:$A$27,0)) -> 2800 | J12: =INDEX(Parametri!$F$31:$F$52,MATCH($B12,Parametri!$A$31:$A$52,0)) -> 0 | K12: =INDEX(N12:S12,MATCH($F$3,$N$4:$S$4,0)) -> 15052.708 | L12: =SUM(N12:S12) -> 46341.858 | M12: =F12*L12 -> 55.197498 | N12: =IF(N$4<$F$3,0,MAX(0,MIN(1,$D12-(N$4-$F$3+1)+1))*($G12*(1+INDEX(Parametri!$E$31:$E$52,MATCH($B12,Parametri!$A$31:$A$52,0)))^(N$4-$H12)+$I12*(1+Parametri!$B$5)^(N$4-Parametri!$B$6)+IF(N$4=$F$3,$J12,0))) -> 0 | O12: =IF(O$4<$F$3,0,MAX(0,MIN(1,$D12-(O$4-$F$3+1)+1))*($G12*(1+INDEX(Parametri!$E$31:$E$52,MATCH($B12,Parametri!$A$31:$A$52,0)))^(O$4-$H12)+$I12*(1+Parametri!$B$5)^(O$4-Parametri!$B$6)+IF(O$4=$F$3,$J12,0))) -> 15052.708 | P12: =IF(P$4<$F$3,0,MAX(0,MIN(1,$D12-(P$4-$F$3+1)+1))*($G12*(1+INDEX(Parametri!$E$31:$E$52,MATCH($B12,Parametri!$A$31:$A$52,0)))^(P$4-$H12)+$I12*(1+Parametri!$B$5)^(P$4-Parametri!$B$6)+IF(P$4=$F$3,$J12,0))) -> 15443.878 | Q12: =IF(Q$4<$F$3,0,MAX(0,MIN(1,$D12-(Q$4-$F$3+1)+1))*($G12*(1+INDEX(Parametri!$E$31:$E$52,MATCH($B12,Parametri!$A$31:$A$52,0)))^(Q$4-$H12)+$I12*(1+Parametri!$B$5)^(Q$4-Parametri!$B$6)+IF(Q$4=$F$3,$J12,0))) -> 15845.273 | R12: =IF(R$4<$F$3,0,MAX(0,MIN(1,$D12-(R$4-$F$3+1)+1))*($G12*(1+INDEX(Parametri!$E$31:$E$52,MATCH($B12,Parametri!$A$31:$A$52,0)))^(R$4-$H12)+$I12*(1+Parametri!$B$5)^(R$4-Parametri!$B$6)+IF(R$4=$F$3,$J12,0))) -> 0 | S12: =IF(S$4<$F$3,0,MAX(0,MIN(1,$D12-(S$4-$F$3+1)+1))*($G12*(1+INDEX(Parametri!$E$31:$E$52,MATCH($B12,Parametri!$A$31:$A$52,0)))^(S$4-$H12)+$I12*(1+Parametri!$B$5)^(S$4-Parametri!$B$6)+IF(S$4=$F$3,$J12,0))) -> 0 | T12: =$F12*N12 -> 0 | U12: =$F12*O12 -> 17.929186 | V12: =$F12*P12 -> 18.395106 | W12: =$F12*Q12 -> 18.873206 | X12: =$F12*R12 -> 0 | Y12: =$F12*S12 -> 0 | Z12: Ripiego a Milano.
B13: TOTALE / ATTESO | F13: =SUM(F6:F12) -> 1 | M13: =SUM(M6:M12) -> 111024.96 | T13: =SUM(T6:T12) -> 0 | U13: =SUM(U6:U12) -> 32669.936 | V13: =SUM(V6:V12) -> 33607.824 | W13: =SUM(W6:W12) -> 34572.794 | X13: =SUM(X6:X12) -> 10174.406 | Y13: =SUM(Y6:Y12) -> 0 | Z13: P(iscrizione) deve sommare a 100%
B15: Scenario più probabile (max P(iscrizione)) | C15: =INDEX($B$6:$B$12,MATCH(MAX($F$6:$F$12),$F$6:$F$12,0)) -> Rotterdam RSM — IBA | L15: =INDEX($L$6:$L$12,MATCH(MAX($F$6:$F$12),$F$6:$F$12,0)) -> 93993.152 | N15: =INDEX($N$6:$N$12,MATCH(MAX($F$6:$F$12),$F$6:$F$12,0)) -> 0 | O15: =INDEX($O$6:$O$12,MATCH(MAX($F$6:$F$12),$F$6:$F$12,0)) -> 30423.675 | P15: =INDEX($P$6:$P$12,MATCH(MAX($F$6:$F$12),$F$6:$F$12,0)) -> 31322.184 | Q15: =INDEX($Q$6:$Q$12,MATCH(MAX($F$6:$F$12),$F$6:$F$12,0)) -> 32247.293 | R15: =INDEX($R$6:$R$12,MATCH(MAX($F$6:$F$12),$F$6:$F$12,0)) -> 0 | S15: =INDEX($S$6:$S$12,MATCH(MAX($F$6:$F$12),$F$6:$F$12,0)) -> 0
B16: Scenario economico (min costo tra opzioni con P ≥ soglia) | C16: =INDEX($B$6:$B$12,MATCH(_xlfn.MINIFS($L$6:$L$12,$F$6:$F$12,">="&Parametri!$B$10),$L$6:$L$12,0)) -> Bocconi — CLEAM/Management/BIEM | L16: =INDEX($L$6:$L$12,MATCH(_xlfn.MINIFS($L$6:$L$12,$F$6:$F$12,">="&Parametri!$B$10),$L$6:$L$12,0)) -> 64114.165 | N16: =INDEX($N$6:$N$12,MATCH(_xlfn.MINIFS($L$6:$L$12,$F$6:$F$12,">="&Parametri!$B$10),$L$6:$L$12,0)) -> 0 | O16: =INDEX($O$6:$O$12,MATCH(_xlfn.MINIFS($L$6:$L$12,$F$6:$F$12,">="&Parametri!$B$10),$L$6:$L$12,0)) -> 20831.145 | P16: =INDEX($P$6:$P$12,MATCH(_xlfn.MINIFS($L$6:$L$12,$F$6:$F$12,">="&Parametri!$B$10),$L$6:$L$12,0)) -> 21366.776 | Q16: =INDEX($Q$6:$Q$12,MATCH(_xlfn.MINIFS($L$6:$L$12,$F$6:$F$12,">="&Parametri!$B$10),$L$6:$L$12,0)) -> 21916.244 | R16: =INDEX($R$6:$R$12,MATCH(_xlfn.MINIFS($L$6:$L$12,$F$6:$F$12,">="&Parametri!$B$10),$L$6:$L$12,0)) -> 0 | S16: =INDEX($S$6:$S$12,MATCH(_xlfn.MINIFS($L$6:$L$12,$F$6:$F$12,">="&Parametri!$B$10),$L$6:$L$12,0)) -> 0
B17: Scenario caro (max costo tra opzioni con P ≥ soglia) | C17: =INDEX($B$6:$B$12,MATCH(_xlfn.MAXIFS($L$6:$L$12,$F$6:$F$12,">="&Parametri!$B$10),$L$6:$L$12,0)) -> ESADE Barcellona — BBA / GGELO | L17: =INDEX($L$6:$L$12,MATCH(_xlfn.MAXIFS($L$6:$L$12,$F$6:$F$12,">="&Parametri!$B$10),$L$6:$L$12,0)) -> 210496.86 | N17: =INDEX($N$6:$N$12,MATCH(_xlfn.MAXIFS($L$6:$L$12,$F$6:$F$12,">="&Parametri!$B$10),$L$6:$L$12,0)) -> 0 | O17: =INDEX($O$6:$O$12,MATCH(_xlfn.MAXIFS($L$6:$L$12,$F$6:$F$12,">="&Parametri!$B$10),$L$6:$L$12,0)) -> 50476.8 | P17: =INDEX($P$6:$P$12,MATCH(_xlfn.MAXIFS($L$6:$L$12,$F$6:$F$12,">="&Parametri!$B$10),$L$6:$L$12,0)) -> 51881.942 | Q17: =INDEX($Q$6:$Q$12,MATCH(_xlfn.MAXIFS($L$6:$L$12,$F$6:$F$12,">="&Parametri!$B$10),$L$6:$L$12,0)) -> 53326.508 | R17: =INDEX($R$6:$R$12,MATCH(_xlfn.MAXIFS($L$6:$L$12,$F$6:$F$12,">="&Parametri!$B$10),$L$6:$L$12,0)) -> 54811.615 | S17: =INDEX($S$6:$S$12,MATCH(_xlfn.MAXIFS($L$6:$L$12,$F$6:$F$12,">="&Parametri!$B$10),$L$6:$L$12,0)) -> 0

Sheet Iacopo
A1: IACOPO — cascata di opzioni, probabilità e costi
